C:\Users\valen\AppData\Local\Programs\Python\Python37-32\python.exe C:/Users/valen/Desktop/Levothyscan-master/script.py
Recherche de <levothyrox> dans la rubrique <18*sante>
32 page(s) sur le sujet <levothyrox> dans la rubrique <18*sante> (limité à 100 topics par page)
telechargement de page 1 sur 32
telechargement de page 2 sur 32
telechargement de page 3 sur 32
telechargement de page 4 sur 32
telechargement de page 5 sur 32
telechargement de page 6 sur 32
telechargement de page 7 sur 32
telechargement de page 8 sur 32
telechargement de page 9 sur 32
telechargement de page 10 sur 32
telechargement de page 11 sur 32
telechargement de page 12 sur 32
telechargement de page 13 sur 32
telechargement de page 14 sur 32
telechargement de page 15 sur 32
telechargement de page 16 sur 32
telechargement de page 17 sur 32
telechargement de page 18 sur 32
telechargement de page 19 sur 32
telechargement de page 20 sur 32
telechargement de page 21 sur 32
telechargement de page 22 sur 32
telechargement de page 23 sur 32
telechargement de page 24 sur 32
telechargement de page 25 sur 32
telechargement de page 26 sur 32
telechargement de page 27 sur 32
telechargement de page 28 sur 32
telechargement de page 29 sur 32
telechargement de page 30 sur 32
telechargement de page 31 sur 32
telechargement de page 32 sur 32
nb de topic = 6900
1 topics extrait sur 6900. Messages récoltés : 1
2 topics extrait sur 6900. Messages récoltés : 6
3 topics extrait sur 6900. Messages récoltés : 18
4 topics extrait sur 6900. Messages récoltés : 69
5 topics extrait sur 6900. Messages récoltés : 298
6 topics extrait sur 6900. Messages récoltés : 313
7 topics extrait sur 6900. Messages récoltés : 313
8 topics extrait sur 6900. Messages récoltés : 354
9 topics extrait sur 6900. Messages récoltés : 371
10 topics extrait sur 6900. Messages récoltés : 371
11 topics extrait sur 6900. Messages récoltés : 401
12 topics extrait sur 6900. Messages récoltés : 407
13 topics extrait sur 6900. Messages récoltés : 410
14 topics extrait sur 6900. Messages récoltés : 410
15 topics extrait sur 6900. Messages récoltés : 423
16 topics extrait sur 6900. Messages récoltés : 423
17 topics extrait sur 6900. Messages récoltés : 428
18 topics extrait sur 6900. Messages récoltés : 448
19 topics extrait sur 6900. Messages récoltés : 465
20 topics extrait sur 6900. Messages récoltés : 474
21 topics extrait sur 6900. Messages récoltés : 492
22 topics extrait sur 6900. Messages récoltés : 492
23 topics extrait sur 6900. Messages récoltés : 535
24 topics extrait sur 6900. Messages récoltés : 535
25 topics extrait sur 6900. Messages récoltés : 551
26 topics extrait sur 6900. Messages récoltés : 557
27 topics extrait sur 6900. Messages récoltés : 557
28 topics extrait sur 6900. Messages récoltés : 559
29 topics extrait sur 6900. Messages récoltés : 572
30 topics extrait sur 6900. Messages récoltés : 572
31 topics extrait sur 6900. Messages récoltés : 572
32 topics extrait sur 6900. Messages récoltés : 619
33 topics extrait sur 6900. Messages récoltés : 619
34 topics extrait sur 6900. Messages récoltés : 643
35 topics extrait sur 6900. Messages récoltés : 652
36 topics extrait sur 6900. Messages récoltés : 652
37 topics extrait sur 6900. Messages récoltés : 652
38 topics extrait sur 6900. Messages récoltés : 687
39 topics extrait sur 6900. Messages récoltés : 704
40 topics extrait sur 6900. Messages récoltés : 704
41 topics extrait sur 6900. Messages récoltés : 723
42 topics extrait sur 6900. Messages récoltés : 726
43 topics extrait sur 6900. Messages récoltés : 726
44 topics extrait sur 6900. Messages récoltés : 762
45 topics extrait sur 6900. Messages récoltés : 768
46 topics extrait sur 6900. Messages récoltés : 781
47 topics extrait sur 6900. Messages récoltés : 785
48 topics extrait sur 6900. Messages récoltés : 785
49 topics extrait sur 6900. Messages récoltés : 788
50 topics extrait sur 6900. Messages récoltés : 793
51 topics extrait sur 6900. Messages récoltés : 799
52 topics extrait sur 6900. Messages récoltés : 799
53 topics extrait sur 6900. Messages récoltés : 806
54 topics extrait sur 6900. Messages récoltés : 807
55 topics extrait sur 6900. Messages récoltés : 827
56 topics extrait sur 6900. Messages récoltés : 827
57 topics extrait sur 6900. Messages récoltés : 847
58 topics extrait sur 6900. Messages récoltés : 847
59 topics extrait sur 6900. Messages récoltés : 865
60 topics extrait sur 6900. Messages récoltés : 880
61 topics extrait sur 6900. Messages récoltés : 880
62 topics extrait sur 6900. Messages récoltés : 881
63 topics extrait sur 6900. Messages récoltés : 950
64 topics extrait sur 6900. Messages récoltés : 985
65 topics extrait sur 6900. Messages récoltés : 993
66 topics extrait sur 6900. Messages récoltés : 1033
67 topics extrait sur 6900. Messages récoltés : 1034
68 topics extrait sur 6900. Messages récoltés : 1040
69 topics extrait sur 6900. Messages récoltés : 1040
70 topics extrait sur 6900. Messages récoltés : 1046
71 topics extrait sur 6900. Messages récoltés : 1050
72 topics extrait sur 6900. Messages récoltés : 1056
73 topics extrait sur 6900. Messages récoltés : 1056
74 topics extrait sur 6900. Messages récoltés : 1095
75 topics extrait sur 6900. Messages récoltés : 1110
76 topics extrait sur 6900. Messages récoltés : 1130
77 topics extrait sur 6900. Messages récoltés : 1134
78 topics extrait sur 6900. Messages récoltés : 1134
79 topics extrait sur 6900. Messages récoltés : 1248
80 topics extrait sur 6900. Messages récoltés : 1251
81 topics extrait sur 6900. Messages récoltés : 1251
WARNING : topic ">Qui prend ou va prendre L-Thyroxin Henning en remplacement du Lévo ?" contient 13 pages. Risque probable de perte de 50 messages sur 650 pour chaque erreur ci-dessous :
          Code erreur "ConnectionResetError: [WinError 10054] An existing connection was forcibly closed by the remote host"
82 topics extrait sur 6900. Messages récoltés : 1260
83 topics extrait sur 6900. Messages récoltés : 1260
84 topics extrait sur 6900. Messages récoltés : 1310
85 topics extrait sur 6900. Messages récoltés : 1417
86 topics extrait sur 6900. Messages récoltés : 1458
87 topics extrait sur 6900. Messages récoltés : 1560
88 topics extrait sur 6900. Messages récoltés : 1663
89 topics extrait sur 6900. Messages récoltés : 1695
90 topics extrait sur 6900. Messages récoltés : 1713
91 topics extrait sur 6900. Messages récoltés : 1834
92 topics extrait sur 6900. Messages récoltés : 1886
93 topics extrait sur 6900. Messages récoltés : 1937
94 topics extrait sur 6900. Messages récoltés : 1949
95 topics extrait sur 6900. Messages récoltés : 1957
96 topics extrait sur 6900. Messages récoltés : 1961
97 topics extrait sur 6900. Messages récoltés : 2064
98 topics extrait sur 6900. Messages récoltés : 2130
99 topics extrait sur 6900. Messages récoltés : 2231
100 topics extrait sur 6900. Messages récoltés : 2239
101 topics extrait sur 6900. Messages récoltés : 2270
102 topics extrait sur 6900. Messages récoltés : 2276
103 topics extrait sur 6900. Messages récoltés : 2276
104 topics extrait sur 6900. Messages récoltés : 2297
105 topics extrait sur 6900. Messages récoltés : 2306
106 topics extrait sur 6900. Messages récoltés : 2318
107 topics extrait sur 6900. Messages récoltés : 2318
108 topics extrait sur 6900. Messages récoltés : 2318
109 topics extrait sur 6900. Messages récoltés : 2353
110 topics extrait sur 6900. Messages récoltés : 2353
111 topics extrait sur 6900. Messages récoltés : 2368
112 topics extrait sur 6900. Messages récoltés : 2368
113 topics extrait sur 6900. Messages récoltés : 2396
114 topics extrait sur 6900. Messages récoltés : 2396
115 topics extrait sur 6900. Messages récoltés : 2420
116 topics extrait sur 6900. Messages récoltés : 2426
117 topics extrait sur 6900. Messages récoltés : 2426
118 topics extrait sur 6900. Messages récoltés : 2444
119 topics extrait sur 6900. Messages récoltés : 2444
120 topics extrait sur 6900. Messages récoltés : 2458
121 topics extrait sur 6900. Messages récoltés : 2458
122 topics extrait sur 6900. Messages récoltés : 2467
123 topics extrait sur 6900. Messages récoltés : 2476
124 topics extrait sur 6900. Messages récoltés : 2484
125 topics extrait sur 6900. Messages récoltés : 2502
126 topics extrait sur 6900. Messages récoltés : 2502
127 topics extrait sur 6900. Messages récoltés : 2517
128 topics extrait sur 6900. Messages récoltés : 2517
129 topics extrait sur 6900. Messages récoltés : 2517
130 topics extrait sur 6900. Messages récoltés : 2594
131 topics extrait sur 6900. Messages récoltés : 2657
132 topics extrait sur 6900. Messages récoltés : 2657
133 topics extrait sur 6900. Messages récoltés : 2657
134 topics extrait sur 6900. Messages récoltés : 2736
135 topics extrait sur 6900. Messages récoltés : 2787
136 topics extrait sur 6900. Messages récoltés : 2794
137 topics extrait sur 6900. Messages récoltés : 2794
138 topics extrait sur 6900. Messages récoltés : 2822
139 topics extrait sur 6900. Messages récoltés : 2822
140 topics extrait sur 6900. Messages récoltés : 2833
141 topics extrait sur 6900. Messages récoltés : 2834
142 topics extrait sur 6900. Messages récoltés : 2834
143 topics extrait sur 6900. Messages récoltés : 2851
144 topics extrait sur 6900. Messages récoltés : 2866
145 topics extrait sur 6900. Messages récoltés : 2866
146 topics extrait sur 6900. Messages récoltés : 2883
147 topics extrait sur 6900. Messages récoltés : 2891
148 topics extrait sur 6900. Messages récoltés : 2901
149 topics extrait sur 6900. Messages récoltés : 2901
150 topics extrait sur 6900. Messages récoltés : 2913
151 topics extrait sur 6900. Messages récoltés : 2963
152 topics extrait sur 6900. Messages récoltés : 2963
153 topics extrait sur 6900. Messages récoltés : 2993
154 topics extrait sur 6900. Messages récoltés : 2993
155 topics extrait sur 6900. Messages récoltés : 3006
156 topics extrait sur 6900. Messages récoltés : 3006
157 topics extrait sur 6900. Messages récoltés : 3026
158 topics extrait sur 6900. Messages récoltés : 3042
159 topics extrait sur 6900. Messages récoltés : 3042
160 topics extrait sur 6900. Messages récoltés : 3042
161 topics extrait sur 6900. Messages récoltés : 3070
162 topics extrait sur 6900. Messages récoltés : 3070
163 topics extrait sur 6900. Messages récoltés : 3090
164 topics extrait sur 6900. Messages récoltés : 3097
165 topics extrait sur 6900. Messages récoltés : 3196
166 topics extrait sur 6900. Messages récoltés : 3198
167 topics extrait sur 6900. Messages récoltés : 3248
168 topics extrait sur 6900. Messages récoltés : 3289
169 topics extrait sur 6900. Messages récoltés : 3289
170 topics extrait sur 6900. Messages récoltés : 3334
171 topics extrait sur 6900. Messages récoltés : 3346
172 topics extrait sur 6900. Messages récoltés : 3359
173 topics extrait sur 6900. Messages récoltés : 3360
174 topics extrait sur 6900. Messages récoltés : 3360
175 topics extrait sur 6900. Messages récoltés : 3390
176 topics extrait sur 6900. Messages récoltés : 3394
177 topics extrait sur 6900. Messages récoltés : 3395
178 topics extrait sur 6900. Messages récoltés : 3399
179 topics extrait sur 6900. Messages récoltés : 3399
180 topics extrait sur 6900. Messages récoltés : 3447
181 topics extrait sur 6900. Messages récoltés : 3447
182 topics extrait sur 6900. Messages récoltés : 3456
183 topics extrait sur 6900. Messages récoltés : 3498
184 topics extrait sur 6900. Messages récoltés : 3577
185 topics extrait sur 6900. Messages récoltés : 3599
186 topics extrait sur 6900. Messages récoltés : 3599
187 topics extrait sur 6900. Messages récoltés : 3623
188 topics extrait sur 6900. Messages récoltés : 3623
189 topics extrait sur 6900. Messages récoltés : 3626
190 topics extrait sur 6900. Messages récoltés : 3638
191 topics extrait sur 6900. Messages récoltés : 3638
192 topics extrait sur 6900. Messages récoltés : 3654
193 topics extrait sur 6900. Messages récoltés : 3658
194 topics extrait sur 6900. Messages récoltés : 3672
195 topics extrait sur 6900. Messages récoltés : 3678
196 topics extrait sur 6900. Messages récoltés : 3678
197 topics extrait sur 6900. Messages récoltés : 3694
198 topics extrait sur 6900. Messages récoltés : 3696
199 topics extrait sur 6900. Messages récoltés : 3696
200 topics extrait sur 6900. Messages récoltés : 3722
201 topics extrait sur 6900. Messages récoltés : 3726
202 topics extrait sur 6900. Messages récoltés : 3726
203 topics extrait sur 6900. Messages récoltés : 3744
204 topics extrait sur 6900. Messages récoltés : 3745
205 topics extrait sur 6900. Messages récoltés : 3746
206 topics extrait sur 6900. Messages récoltés : 3753
207 topics extrait sur 6900. Messages récoltés : 3753
208 topics extrait sur 6900. Messages récoltés : 3789
209 topics extrait sur 6900. Messages récoltés : 3793
210 topics extrait sur 6900. Messages récoltés : 3793
211 topics extrait sur 6900. Messages récoltés : 3833
212 topics extrait sur 6900. Messages récoltés : 3836
213 topics extrait sur 6900. Messages récoltés : 3836
214 topics extrait sur 6900. Messages récoltés : 3849
215 topics extrait sur 6900. Messages récoltés : 3849
216 topics extrait sur 6900. Messages récoltés : 3858
217 topics extrait sur 6900. Messages récoltés : 3870
218 topics extrait sur 6900. Messages récoltés : 3889
219 topics extrait sur 6900. Messages récoltés : 3889
220 topics extrait sur 6900. Messages récoltés : 3905
221 topics extrait sur 6900. Messages récoltés : 3905
222 topics extrait sur 6900. Messages récoltés : 3925
223 topics extrait sur 6900. Messages récoltés : 3925
224 topics extrait sur 6900. Messages récoltés : 3939
225 topics extrait sur 6900. Messages récoltés : 3963
226 topics extrait sur 6900. Messages récoltés : 3966
227 topics extrait sur 6900. Messages récoltés : 3967
228 topics extrait sur 6900. Messages récoltés : 3967
229 topics extrait sur 6900. Messages récoltés : 3970
230 topics extrait sur 6900. Messages récoltés : 3983
231 topics extrait sur 6900. Messages récoltés : 3994
232 topics extrait sur 6900. Messages récoltés : 3999
233 topics extrait sur 6900. Messages récoltés : 3999
234 topics extrait sur 6900. Messages récoltés : 4012
235 topics extrait sur 6900. Messages récoltés : 4038
236 topics extrait sur 6900. Messages récoltés : 4047
237 topics extrait sur 6900. Messages récoltés : 4047
238 topics extrait sur 6900. Messages récoltés : 4058
239 topics extrait sur 6900. Messages récoltés : 4061
WARNING : topic ">ICI  C&#039;EST  CHEZ  VOUS" contient 300 pages. Risque probable de perte de 50 messages sur 15000 pour chaque erreur ci-dessous :
          Code erreur "ConnectionResetError: [WinError 10054] An existing connection was forcibly closed by the remote host"
240 topics extrait sur 6900. Messages récoltés : 4069
241 topics extrait sur 6900. Messages récoltés : 4222
Exception in thread Thread-429:
Traceback (most recent call last):
  File "C:\Users\valen\AppData\Local\Programs\Python\Python37-32\lib\urllib\request.py", line 1317, in do_open
    encode_chunked=req.has_header('Transfer-encoding'))
  File "C:\Users\valen\AppData\Local\Programs\Python\Python37-32\lib\http\client.py", line 1229, in request
    self._send_request(method, url, body, headers, encode_chunked)
  File "C:\Users\valen\AppData\Local\Programs\Python\Python37-32\lib\http\client.py", line 1275, in _send_request
    self.endheaders(body, encode_chunked=encode_chunked)
  File "C:\Users\valen\AppData\Local\Programs\Python\Python37-32\lib\http\client.py", line 1224, in endheaders
    self._send_output(message_body, encode_chunked=encode_chunked)
  File "C:\Users\valen\AppData\Local\Programs\Python\Python37-32\lib\http\client.py", line 1016, in _send_output
    self.send(msg)
  File "C:\Users\valen\AppData\Local\Programs\Python\Python37-32\lib\http\client.py", line 956, in send
    self.connect()
  File "C:\Users\valen\AppData\Local\Programs\Python\Python37-32\lib\http\client.py", line 928, in connect
    (self.host,self.port), self.timeout, self.source_address)
  File "C:\Users\valen\AppData\Local\Programs\Python\Python37-32\lib\socket.py", line 727, in create_connection
    raise err
  File "C:\Users\valen\AppData\Local\Programs\Python\Python37-32\lib\socket.py", line 716, in create_connection
    sock.connect(sa)
TimeoutError: [WinError 10060] Une tentative de connexion a échoué car le parti connecté n’a pas répondu convenablement au-delà d’une certaine durée ou une connexion établie a échoué car l’hôte de connexion n’a pas répondu

During handling of the above exception, another exception occurred:

Traceback (most recent call last):
  File "C:/Users/valen/Desktop/Levothyscan-master/script.py", line 49, in run
    with urllib.request.urlopen(self.url) as rep:
  File "C:\Users\valen\AppData\Local\Programs\Python\Python37-32\lib\urllib\request.py", line 222, in urlopen
    return opener.open(url, data, timeout)
  File "C:\Users\valen\AppData\Local\Programs\Python\Python37-32\lib\urllib\request.py", line 525, in open
    response = self._open(req, data)
  File "C:\Users\valen\AppData\Local\Programs\Python\Python37-32\lib\urllib\request.py", line 543, in _open
    '_open', req)
  File "C:\Users\valen\AppData\Local\Programs\Python\Python37-32\lib\urllib\request.py", line 503, in _call_chain
    result = func(*args)
  File "C:\Users\valen\AppData\Local\Programs\Python\Python37-32\lib\urllib\request.py", line 1345, in http_open
    return self.do_open(http.client.HTTPConnection, req)
  File "C:\Users\valen\AppData\Local\Programs\Python\Python37-32\lib\urllib\request.py", line 1319, in do_open
    raise URLError(err)
urllib.error.URLError: <urlopen error [WinError 10060] Une tentative de connexion a échoué car le parti connecté n’a pas répondu convenablement au-delà d’une certaine durée ou une connexion établie a échoué car l’hôte de connexion n’a pas répondu>

During handling of the above exception, another exception occurred:

Traceback (most recent call last):
  File "C:\Users\valen\AppData\Local\Programs\Python\Python37-32\lib\threading.py", line 917, in _bootstrap_inner
    self.run()
  File "C:/Users/valen/Desktop/Levothyscan-master/script.py", line 51, in run
    except (http.client.IncompleteRead) as e:
NameError: name 'http' is not defined

Exception in thread Thread-416:
Traceback (most recent call last):
  File "C:\Users\valen\AppData\Local\Programs\Python\Python37-32\lib\urllib\request.py", line 1317, in do_open
    encode_chunked=req.has_header('Transfer-encoding'))
  File "C:\Users\valen\AppData\Local\Programs\Python\Python37-32\lib\http\client.py", line 1229, in request
    self._send_request(method, url, body, headers, encode_chunked)
  File "C:\Users\valen\AppData\Local\Programs\Python\Python37-32\lib\http\client.py", line 1275, in _send_request
    self.endheaders(body, encode_chunked=encode_chunked)
  File "C:\Users\valen\AppData\Local\Programs\Python\Python37-32\lib\http\client.py", line 1224, in endheaders
    self._send_output(message_body, encode_chunked=encode_chunked)
  File "C:\Users\valen\AppData\Local\Programs\Python\Python37-32\lib\http\client.py", line 1016, in _send_output
    self.send(msg)
  File "C:\Users\valen\AppData\Local\Programs\Python\Python37-32\lib\http\client.py", line 956, in send
    self.connect()
  File "C:\Users\valen\AppData\Local\Programs\Python\Python37-32\lib\http\client.py", line 928, in connect
    (self.host,self.port), self.timeout, self.source_address)
  File "C:\Users\valen\AppData\Local\Programs\Python\Python37-32\lib\socket.py", line 727, in create_connection
    raise err
  File "C:\Users\valen\AppData\Local\Programs\Python\Python37-32\lib\socket.py", line 716, in create_connection
    sock.connect(sa)
TimeoutError: [WinError 10060] Une tentative de connexion a échoué car le parti connecté n’a pas répondu convenablement au-delà d’une certaine durée ou une connexion établie a échoué car l’hôte de connexion n’a pas répondu

During handling of the above exception, another exception occurred:

Traceback (most recent call last):
  File "C:/Users/valen/Desktop/Levothyscan-master/script.py", line 49, in run
    with urllib.request.urlopen(self.url) as rep:
  File "C:\Users\valen\AppData\Local\Programs\Python\Python37-32\lib\urllib\request.py", line 222, in urlopen
    return opener.open(url, data, timeout)
  File "C:\Users\valen\AppData\Local\Programs\Python\Python37-32\lib\urllib\request.py", line 525, in open
    response = self._open(req, data)
  File "C:\Users\valen\AppData\Local\Programs\Python\Python37-32\lib\urllib\request.py", line 543, in _open
    '_open', req)
  File "C:\Users\valen\AppData\Local\Programs\Python\Python37-32\lib\urllib\request.py", line 503, in _call_chain
    result = func(*args)
  File "C:\Users\valen\AppData\Local\Programs\Python\Python37-32\lib\urllib\request.py", line 1345, in http_open
    return self.do_open(http.client.HTTPConnection, req)
  File "C:\Users\valen\AppData\Local\Programs\Python\Python37-32\lib\urllib\request.py", line 1319, in do_open
    raise URLError(err)
urllib.error.URLError: <urlopen error [WinError 10060] Une tentative de connexion a échoué car le parti connecté n’a pas répondu convenablement au-delà d’une certaine durée ou une connexion établie a échoué car l’hôte de connexion n’a pas répondu>

During handling of the above exception, another exception occurred:

Traceback (most recent call last):
  File "C:\Users\valen\AppData\Local\Programs\Python\Python37-32\lib\threading.py", line 917, in _bootstrap_inner
    self.run()
  File "C:/Users/valen/Desktop/Levothyscan-master/script.py", line 51, in run
    except (http.client.IncompleteRead) as e:
NameError: name 'http' is not defined
Exception in thread Thread-426:
Traceback (most recent call last):
  File "C:\Users\valen\AppData\Local\Programs\Python\Python37-32\lib\urllib\request.py", line 1317, in do_open
    encode_chunked=req.has_header('Transfer-encoding'))
  File "C:\Users\valen\AppData\Local\Programs\Python\Python37-32\lib\http\client.py", line 1229, in request
    self._send_request(method, url, body, headers, encode_chunked)
  File "C:\Users\valen\AppData\Local\Programs\Python\Python37-32\lib\http\client.py", line 1275, in _send_request
    self.endheaders(body, encode_chunked=encode_chunked)
  File "C:\Users\valen\AppData\Local\Programs\Python\Python37-32\lib\http\client.py", line 1224, in endheaders
    self._send_output(message_body, encode_chunked=encode_chunked)
  File "C:\Users\valen\AppData\Local\Programs\Python\Python37-32\lib\http\client.py", line 1016, in _send_output
    self.send(msg)
  File "C:\Users\valen\AppData\Local\Programs\Python\Python37-32\lib\http\client.py", line 956, in send
    self.connect()
  File "C:\Users\valen\AppData\Local\Programs\Python\Python37-32\lib\http\client.py", line 928, in connect
    (self.host,self.port), self.timeout, self.source_address)
  File "C:\Users\valen\AppData\Local\Programs\Python\Python37-32\lib\socket.py", line 727, in create_connection
    raise err
  File "C:\Users\valen\AppData\Local\Programs\Python\Python37-32\lib\socket.py", line 716, in create_connection
    sock.connect(sa)
TimeoutError: [WinError 10060] Une tentative de connexion a échoué car le parti connecté n’a pas répondu convenablement au-delà d’une certaine durée ou une connexion établie a échoué car l’hôte de connexion n’a pas répondu

During handling of the above exception, another exception occurred:

Traceback (most recent call last):
  File "C:/Users/valen/Desktop/Levothyscan-master/script.py", line 49, in run
    with urllib.request.urlopen(self.url) as rep:
  File "C:\Users\valen\AppData\Local\Programs\Python\Python37-32\lib\urllib\request.py", line 222, in urlopen
    return opener.open(url, data, timeout)
  File "C:\Users\valen\AppData\Local\Programs\Python\Python37-32\lib\urllib\request.py", line 525, in open
    response = self._open(req, data)
  File "C:\Users\valen\AppData\Local\Programs\Python\Python37-32\lib\urllib\request.py", line 543, in _open
    '_open', req)
  File "C:\Users\valen\AppData\Local\Programs\Python\Python37-32\lib\urllib\request.py", line 503, in _call_chain
    result = func(*args)
  File "C:\Users\valen\AppData\Local\Programs\Python\Python37-32\lib\urllib\request.py", line 1345, in http_open
    return self.do_open(http.client.HTTPConnection, req)
  File "C:\Users\valen\AppData\Local\Programs\Python\Python37-32\lib\urllib\request.py", line 1319, in do_open
    raise URLError(err)
urllib.error.URLError: <urlopen error [WinError 10060] Une tentative de connexion a échoué car le parti connecté n’a pas répondu convenablement au-delà d’une certaine durée ou une connexion établie a échoué car l’hôte de connexion n’a pas répondu>

During handling of the above exception, another exception occurred:

Traceback (most recent call last):
  File "C:\Users\valen\AppData\Local\Programs\Python\Python37-32\lib\threading.py", line 917, in _bootstrap_inner
    self.run()
  File "C:/Users/valen/Desktop/Levothyscan-master/script.py", line 51, in run
    except (http.client.IncompleteRead) as e:
NameError: name 'http' is not defined
Exception in thread Thread-350:
Traceback (most recent call last):
  File "C:\Users\valen\AppData\Local\Programs\Python\Python37-32\lib\urllib\request.py", line 1317, in do_open
    encode_chunked=req.has_header('Transfer-encoding'))
  File "C:\Users\valen\AppData\Local\Programs\Python\Python37-32\lib\http\client.py", line 1229, in request
    self._send_request(method, url, body, headers, encode_chunked)
  File "C:\Users\valen\AppData\Local\Programs\Python\Python37-32\lib\http\client.py", line 1275, in _send_request
    self.endheaders(body, encode_chunked=encode_chunked)
  File "C:\Users\valen\AppData\Local\Programs\Python\Python37-32\lib\http\client.py", line 1224, in endheaders
    self._send_output(message_body, encode_chunked=encode_chunked)
  File "C:\Users\valen\AppData\Local\Programs\Python\Python37-32\lib\http\client.py", line 1016, in _send_output
    self.send(msg)
  File "C:\Users\valen\AppData\Local\Programs\Python\Python37-32\lib\http\client.py", line 956, in send
    self.connect()
  File "C:\Users\valen\AppData\Local\Programs\Python\Python37-32\lib\http\client.py", line 928, in connect
    (self.host,self.port), self.timeout, self.source_address)
  File "C:\Users\valen\AppData\Local\Programs\Python\Python37-32\lib\socket.py", line 727, in create_connection
    raise err
  File "C:\Users\valen\AppData\Local\Programs\Python\Python37-32\lib\socket.py", line 716, in create_connection
    sock.connect(sa)
TimeoutError: [WinError 10060] Une tentative de connexion a échoué car le parti connecté n’a pas répondu convenablement au-delà d’une certaine durée ou une connexion établie a échoué car l’hôte de connexion n’a pas répondu

During handling of the above exception, another exception occurred:

Traceback (most recent call last):
  File "C:/Users/valen/Desktop/Levothyscan-master/script.py", line 49, in run
    with urllib.request.urlopen(self.url) as rep:
  File "C:\Users\valen\AppData\Local\Programs\Python\Python37-32\lib\urllib\request.py", line 222, in urlopen
    return opener.open(url, data, timeout)
  File "C:\Users\valen\AppData\Local\Programs\Python\Python37-32\lib\urllib\request.py", line 525, in open
    response = self._open(req, data)
  File "C:\Users\valen\AppData\Local\Programs\Python\Python37-32\lib\urllib\request.py", line 543, in _open
    '_open', req)
  File "C:\Users\valen\AppData\Local\Programs\Python\Python37-32\lib\urllib\request.py", line 503, in _call_chain
    result = func(*args)
  File "C:\Users\valen\AppData\Local\Programs\Python\Python37-32\lib\urllib\request.py", line 1345, in http_open
    return self.do_open(http.client.HTTPConnection, req)
  File "C:\Users\valen\AppData\Local\Programs\Python\Python37-32\lib\urllib\request.py", line 1319, in do_open
    raise URLError(err)
urllib.error.URLError: <urlopen error [WinError 10060] Une tentative de connexion a échoué car le parti connecté n’a pas répondu convenablement au-delà d’une certaine durée ou une connexion établie a échoué car l’hôte de connexion n’a pas répondu>

During handling of the above exception, another exception occurred:

Traceback (most recent call last):
  File "C:\Users\valen\AppData\Local\Programs\Python\Python37-32\lib\threading.py", line 917, in _bootstrap_inner
    self.run()
  File "C:/Users/valen/Desktop/Levothyscan-master/script.py", line 51, in run
    except (http.client.IncompleteRead) as e:
NameError: name 'http' is not defined
Exception in thread Thread-418:
Traceback (most recent call last):
  File "C:\Users\valen\AppData\Local\Programs\Python\Python37-32\lib\urllib\request.py", line 1317, in do_open
    encode_chunked=req.has_header('Transfer-encoding'))
  File "C:\Users\valen\AppData\Local\Programs\Python\Python37-32\lib\http\client.py", line 1229, in request
    self._send_request(method, url, body, headers, encode_chunked)
  File "C:\Users\valen\AppData\Local\Programs\Python\Python37-32\lib\http\client.py", line 1275, in _send_request
    self.endheaders(body, encode_chunked=encode_chunked)
  File "C:\Users\valen\AppData\Local\Programs\Python\Python37-32\lib\http\client.py", line 1224, in endheaders
    self._send_output(message_body, encode_chunked=encode_chunked)
  File "C:\Users\valen\AppData\Local\Programs\Python\Python37-32\lib\http\client.py", line 1016, in _send_output
    self.send(msg)
  File "C:\Users\valen\AppData\Local\Programs\Python\Python37-32\lib\http\client.py", line 956, in send
    self.connect()
  File "C:\Users\valen\AppData\Local\Programs\Python\Python37-32\lib\http\client.py", line 928, in connect
    (self.host,self.port), self.timeout, self.source_address)
  File "C:\Users\valen\AppData\Local\Programs\Python\Python37-32\lib\socket.py", line 727, in create_connection
    raise err
  File "C:\Users\valen\AppData\Local\Programs\Python\Python37-32\lib\socket.py", line 716, in create_connection
    sock.connect(sa)
TimeoutError: [WinError 10060] Une tentative de connexion a échoué car le parti connecté n’a pas répondu convenablement au-delà d’une certaine durée ou une connexion établie a échoué car l’hôte de connexion n’a pas répondu

During handling of the above exception, another exception occurred:

Traceback (most recent call last):
  File "C:/Users/valen/Desktop/Levothyscan-master/script.py", line 49, in run
    with urllib.request.urlopen(self.url) as rep:
  File "C:\Users\valen\AppData\Local\Programs\Python\Python37-32\lib\urllib\request.py", line 222, in urlopen
    return opener.open(url, data, timeout)
  File "C:\Users\valen\AppData\Local\Programs\Python\Python37-32\lib\urllib\request.py", line 525, in open
    response = self._open(req, data)
  File "C:\Users\valen\AppData\Local\Programs\Python\Python37-32\lib\urllib\request.py", line 543, in _open
    '_open', req)
  File "C:\Users\valen\AppData\Local\Programs\Python\Python37-32\lib\urllib\request.py", line 503, in _call_chain
    result = func(*args)
  File "C:\Users\valen\AppData\Local\Programs\Python\Python37-32\lib\urllib\request.py", line 1345, in http_open
    return self.do_open(http.client.HTTPConnection, req)
  File "C:\Users\valen\AppData\Local\Programs\Python\Python37-32\lib\urllib\request.py", line 1319, in do_open
    raise URLError(err)
urllib.error.URLError: <urlopen error [WinError 10060] Une tentative de connexion a échoué car le parti connecté n’a pas répondu convenablement au-delà d’une certaine durée ou une connexion établie a échoué car l’hôte de connexion n’a pas répondu>

During handling of the above exception, another exception occurred:

Traceback (most recent call last):
  File "C:\Users\valen\AppData\Local\Programs\Python\Python37-32\lib\threading.py", line 917, in _bootstrap_inner
    self.run()
  File "C:/Users/valen/Desktop/Levothyscan-master/script.py", line 51, in run
    except (http.client.IncompleteRead) as e:
NameError: name 'http' is not defined




Exception in thread Thread-386:
Traceback (most recent call last):
  File "C:\Users\valen\AppData\Local\Programs\Python\Python37-32\lib\urllib\request.py", line 1317, in do_open
    encode_chunked=req.has_header('Transfer-encoding'))
  File "C:\Users\valen\AppData\Local\Programs\Python\Python37-32\lib\http\client.py", line 1229, in request
    self._send_request(method, url, body, headers, encode_chunked)
  File "C:\Users\valen\AppData\Local\Programs\Python\Python37-32\lib\http\client.py", line 1275, in _send_request
    self.endheaders(body, encode_chunked=encode_chunked)
  File "C:\Users\valen\AppData\Local\Programs\Python\Python37-32\lib\http\client.py", line 1224, in endheaders
    self._send_output(message_body, encode_chunked=encode_chunked)
  File "C:\Users\valen\AppData\Local\Programs\Python\Python37-32\lib\http\client.py", line 1016, in _send_output
    self.send(msg)
  File "C:\Users\valen\AppData\Local\Programs\Python\Python37-32\lib\http\client.py", line 956, in send
    self.connect()
  File "C:\Users\valen\AppData\Local\Programs\Python\Python37-32\lib\http\client.py", line 928, in connect
    (self.host,self.port), self.timeout, self.source_address)
  File "C:\Users\valen\AppData\Local\Programs\Python\Python37-32\lib\socket.py", line 727, in create_connection
    raise err
  File "C:\Users\valen\AppData\Local\Programs\Python\Python37-32\lib\socket.py", line 716, in create_connection
    sock.connect(sa)
TimeoutError: [WinError 10060] Une tentative de connexion a échoué car le parti connecté n’a pas répondu convenablement au-delà d’une certaine durée ou une connexion établie a échoué car l’hôte de connexion n’a pas répondu

During handling of the above exception, another exception occurred:

Traceback (most recent call last):
  File "C:/Users/valen/Desktop/Levothyscan-master/script.py", line 49, in run
    with urllib.request.urlopen(self.url) as rep:
  File "C:\Users\valen\AppData\Local\Programs\Python\Python37-32\lib\urllib\request.py", line 222, in urlopen
    return opener.open(url, data, timeout)
  File "C:\Users\valen\AppData\Local\Programs\Python\Python37-32\lib\urllib\request.py", line 525, in open
    response = self._open(req, data)
  File "C:\Users\valen\AppData\Local\Programs\Python\Python37-32\lib\urllib\request.py", line 543, in _open
    '_open', req)
  File "C:\Users\valen\AppData\Local\Programs\Python\Python37-32\lib\urllib\request.py", line 503, in _call_chain
    result = func(*args)
  File "C:\Users\valen\AppData\Local\Programs\Python\Python37-32\lib\urllib\request.py", line 1345, in http_open
    return self.do_open(http.client.HTTPConnection, req)
  File "C:\Users\valen\AppData\Local\Programs\Python\Python37-32\lib\urllib\request.py", line 1319, in do_open
    raise URLError(err)
urllib.error.URLError: <urlopen error [WinError 10060] Une tentative de connexion a échoué car le parti connecté n’a pas répondu convenablement au-delà d’une certaine durée ou une connexion établie a échoué car l’hôte de connexion n’a pas répondu>

During handling of the above exception, another exception occurred:

Traceback (most recent call last):
  File "C:\Users\valen\AppData\Local\Programs\Python\Python37-32\lib\threading.py", line 917, in _bootstrap_inner
    self.run()
  File "C:/Users/valen/Desktop/Levothyscan-master/script.py", line 51, in run
    except (http.client.IncompleteRead) as e:
NameError: name 'http' is not defined
Exception in thread Thread-355:
Traceback (most recent call last):
  File "C:\Users\valen\AppData\Local\Programs\Python\Python37-32\lib\urllib\request.py", line 1317, in do_open
    encode_chunked=req.has_header('Transfer-encoding'))
  File "C:\Users\valen\AppData\Local\Programs\Python\Python37-32\lib\http\client.py", line 1229, in request
    self._send_request(method, url, body, headers, encode_chunked)
  File "C:\Users\valen\AppData\Local\Programs\Python\Python37-32\lib\http\client.py", line 1275, in _send_request
    self.endheaders(body, encode_chunked=encode_chunked)
  File "C:\Users\valen\AppData\Local\Programs\Python\Python37-32\lib\http\client.py", line 1224, in endheaders
    self._send_output(message_body, encode_chunked=encode_chunked)
  File "C:\Users\valen\AppData\Local\Programs\Python\Python37-32\lib\http\client.py", line 1016, in _send_output
    self.send(msg)
  File "C:\Users\valen\AppData\Local\Programs\Python\Python37-32\lib\http\client.py", line 956, in send
    self.connect()
  File "C:\Users\valen\AppData\Local\Programs\Python\Python37-32\lib\http\client.py", line 928, in connect
    (self.host,self.port), self.timeout, self.source_address)
  File "C:\Users\valen\AppData\Local\Programs\Python\Python37-32\lib\socket.py", line 727, in create_connection
    raise err
  File "C:\Users\valen\AppData\Local\Programs\Python\Python37-32\lib\socket.py", line 716, in create_connection
    sock.connect(sa)
TimeoutError: [WinError 10060] Une tentative de connexion a échoué car le parti connecté n’a pas répondu convenablement au-delà d’une certaine durée ou une connexion établie a échoué car l’hôte de connexion n’a pas répondu

During handling of the above exception, another exception occurred:

Traceback (most recent call last):
  File "C:/Users/valen/Desktop/Levothyscan-master/script.py", line 49, in run
    with urllib.request.urlopen(self.url) as rep:
  File "C:\Users\valen\AppData\Local\Programs\Python\Python37-32\lib\urllib\request.py", line 222, in urlopen
    return opener.open(url, data, timeout)
  File "C:\Users\valen\AppData\Local\Programs\Python\Python37-32\lib\urllib\request.py", line 525, in open
    response = self._open(req, data)
  File "C:\Users\valen\AppData\Local\Programs\Python\Python37-32\lib\urllib\request.py", line 543, in _open
    '_open', req)
  File "C:\Users\valen\AppData\Local\Programs\Python\Python37-32\lib\urllib\request.py", line 503, in _call_chain
    result = func(*args)
  File "C:\Users\valen\AppData\Local\Programs\Python\Python37-32\lib\urllib\request.py", line 1345, in http_open
    return self.do_open(http.client.HTTPConnection, req)
  File "C:\Users\valen\AppData\Local\Programs\Python\Python37-32\lib\urllib\request.py", line 1319, in do_open
    raise URLError(err)
urllib.error.URLError: <urlopen error [WinError 10060] Une tentative de connexion a échoué car le parti connecté n’a pas répondu convenablement au-delà d’une certaine durée ou une connexion établie a échoué car l’hôte de connexion n’a pas répondu>

During handling of the above exception, another exception occurred:

Traceback (most recent call last):
  File "C:\Users\valen\AppData\Local\Programs\Python\Python37-32\lib\threading.py", line 917, in _bootstrap_inner
    self.run()
  File "C:/Users/valen/Desktop/Levothyscan-master/script.py", line 51, in run
    except (http.client.IncompleteRead) as e:
NameError: name 'http' is not defined
Exception in thread Thread-322:
Traceback (most recent call last):
  File "C:\Users\valen\AppData\Local\Programs\Python\Python37-32\lib\urllib\request.py", line 1317, in do_open
    encode_chunked=req.has_header('Transfer-encoding'))
  File "C:\Users\valen\AppData\Local\Programs\Python\Python37-32\lib\http\client.py", line 1229, in request
    self._send_request(method, url, body, headers, encode_chunked)
  File "C:\Users\valen\AppData\Local\Programs\Python\Python37-32\lib\http\client.py", line 1275, in _send_request
    self.endheaders(body, encode_chunked=encode_chunked)
  File "C:\Users\valen\AppData\Local\Programs\Python\Python37-32\lib\http\client.py", line 1224, in endheaders
    self._send_output(message_body, encode_chunked=encode_chunked)
  File "C:\Users\valen\AppData\Local\Programs\Python\Python37-32\lib\http\client.py", line 1016, in _send_output
    self.send(msg)
  File "C:\Users\valen\AppData\Local\Programs\Python\Python37-32\lib\http\client.py", line 956, in send
    self.connect()
  File "C:\Users\valen\AppData\Local\Programs\Python\Python37-32\lib\http\client.py", line 928, in connect
    (self.host,self.port), self.timeout, self.source_address)
  File "C:\Users\valen\AppData\Local\Programs\Python\Python37-32\lib\socket.py", line 727, in create_connection
    raise err
  File "C:\Users\valen\AppData\Local\Programs\Python\Python37-32\lib\socket.py", line 716, in create_connection
    sock.connect(sa)
TimeoutError: [WinError 10060] Une tentative de connexion a échoué car le parti connecté n’a pas répondu convenablement au-delà d’une certaine durée ou une connexion établie a échoué car l’hôte de connexion n’a pas répondu

During handling of the above exception, another exception occurred:

Traceback (most recent call last):
  File "C:/Users/valen/Desktop/Levothyscan-master/script.py", line 49, in run
    with urllib.request.urlopen(self.url) as rep:
  File "C:\Users\valen\AppData\Local\Programs\Python\Python37-32\lib\urllib\request.py", line 222, in urlopen
    return opener.open(url, data, timeout)
  File "C:\Users\valen\AppData\Local\Programs\Python\Python37-32\lib\urllib\request.py", line 525, in open
    response = self._open(req, data)
  File "C:\Users\valen\AppData\Local\Programs\Python\Python37-32\lib\urllib\request.py", line 543, in _open
    '_open', req)
  File "C:\Users\valen\AppData\Local\Programs\Python\Python37-32\lib\urllib\request.py", line 503, in _call_chain
    result = func(*args)
  File "C:\Users\valen\AppData\Local\Programs\Python\Python37-32\lib\urllib\request.py", line 1345, in http_open
    return self.do_open(http.client.HTTPConnection, req)
  File "C:\Users\valen\AppData\Local\Programs\Python\Python37-32\lib\urllib\request.py", line 1319, in do_open
    raise URLError(err)
urllib.error.URLError: <urlopen error [WinError 10060] Une tentative de connexion a échoué car le parti connecté n’a pas répondu convenablement au-delà d’une certaine durée ou une connexion établie a échoué car l’hôte de connexion n’a pas répondu>

During handling of the above exception, another exception occurred:

Traceback (most recent call last):
  File "C:\Users\valen\AppData\Local\Programs\Python\Python37-32\lib\threading.py", line 917, in _bootstrap_inner
    self.run()
  File "C:/Users/valen/Desktop/Levothyscan-master/script.py", line 51, in run
    except (http.client.IncompleteRead) as e:
NameError: name 'http' is not defined



Exception in thread Thread-393:
Traceback (most recent call last):
  File "C:\Users\valen\AppData\Local\Programs\Python\Python37-32\lib\urllib\request.py", line 1317, in do_open
    encode_chunked=req.has_header('Transfer-encoding'))
  File "C:\Users\valen\AppData\Local\Programs\Python\Python37-32\lib\http\client.py", line 1229, in request
    self._send_request(method, url, body, headers, encode_chunked)
  File "C:\Users\valen\AppData\Local\Programs\Python\Python37-32\lib\http\client.py", line 1275, in _send_request
    self.endheaders(body, encode_chunked=encode_chunked)
  File "C:\Users\valen\AppData\Local\Programs\Python\Python37-32\lib\http\client.py", line 1224, in endheaders
    self._send_output(message_body, encode_chunked=encode_chunked)
  File "C:\Users\valen\AppData\Local\Programs\Python\Python37-32\lib\http\client.py", line 1016, in _send_output
    self.send(msg)
  File "C:\Users\valen\AppData\Local\Programs\Python\Python37-32\lib\http\client.py", line 956, in send
    self.connect()
  File "C:\Users\valen\AppData\Local\Programs\Python\Python37-32\lib\http\client.py", line 928, in connect
    (self.host,self.port), self.timeout, self.source_address)
  File "C:\Users\valen\AppData\Local\Programs\Python\Python37-32\lib\socket.py", line 727, in create_connection
    raise err
  File "C:\Users\valen\AppData\Local\Programs\Python\Python37-32\lib\socket.py", line 716, in create_connection
    sock.connect(sa)
TimeoutError: [WinError 10060] Une tentative de connexion a échoué car le parti connecté n’a pas répondu convenablement au-delà d’une certaine durée ou une connexion établie a échoué car l’hôte de connexion n’a pas répondu

During handling of the above exception, another exception occurred:

Traceback (most recent call last):
  File "C:/Users/valen/Desktop/Levothyscan-master/script.py", line 49, in run
    with urllib.request.urlopen(self.url) as rep:
  File "C:\Users\valen\AppData\Local\Programs\Python\Python37-32\lib\urllib\request.py", line 222, in urlopen
    return opener.open(url, data, timeout)
  File "C:\Users\valen\AppData\Local\Programs\Python\Python37-32\lib\urllib\request.py", line 525, in open
    response = self._open(req, data)
  File "C:\Users\valen\AppData\Local\Programs\Python\Python37-32\lib\urllib\request.py", line 543, in _open
    '_open', req)
  File "C:\Users\valen\AppData\Local\Programs\Python\Python37-32\lib\urllib\request.py", line 503, in _call_chain
    result = func(*args)
  File "C:\Users\valen\AppData\Local\Programs\Python\Python37-32\lib\urllib\request.py", line 1345, in http_open
    return self.do_open(http.client.HTTPConnection, req)
  File "C:\Users\valen\AppData\Local\Programs\Python\Python37-32\lib\urllib\request.py", line 1319, in do_open
    raise URLError(err)
urllib.error.URLError: <urlopen error [WinError 10060] Une tentative de connexion a échoué car le parti connecté n’a pas répondu convenablement au-delà d’une certaine durée ou une connexion établie a échoué car l’hôte de connexion n’a pas répondu>

During handling of the above exception, another exception occurred:

Traceback (most recent call last):
  File "C:\Users\valen\AppData\Local\Programs\Python\Python37-32\lib\threading.py", line 917, in _bootstrap_inner
    self.run()
  File "C:/Users/valen/Desktop/Levothyscan-master/script.py", line 51, in run
    except (http.client.IncompleteRead) as e:
NameError: name 'http' is not defined

Exception in thread Thread-339:
Traceback (most recent call last):
  File "C:\Users\valen\AppData\Local\Programs\Python\Python37-32\lib\urllib\request.py", line 1317, in do_open
    encode_chunked=req.has_header('Transfer-encoding'))
  File "C:\Users\valen\AppData\Local\Programs\Python\Python37-32\lib\http\client.py", line 1229, in request
    self._send_request(method, url, body, headers, encode_chunked)
  File "C:\Users\valen\AppData\Local\Programs\Python\Python37-32\lib\http\client.py", line 1275, in _send_request
    self.endheaders(body, encode_chunked=encode_chunked)
  File "C:\Users\valen\AppData\Local\Programs\Python\Python37-32\lib\http\client.py", line 1224, in endheaders
    self._send_output(message_body, encode_chunked=encode_chunked)
  File "C:\Users\valen\AppData\Local\Programs\Python\Python37-32\lib\http\client.py", line 1016, in _send_output
    self.send(msg)
  File "C:\Users\valen\AppData\Local\Programs\Python\Python37-32\lib\http\client.py", line 956, in send
    self.connect()
  File "C:\Users\valen\AppData\Local\Programs\Python\Python37-32\lib\http\client.py", line 928, in connect
    (self.host,self.port), self.timeout, self.source_address)
  File "C:\Users\valen\AppData\Local\Programs\Python\Python37-32\lib\socket.py", line 727, in create_connection
    raise err
  File "C:\Users\valen\AppData\Local\Programs\Python\Python37-32\lib\socket.py", line 716, in create_connection
    sock.connect(sa)
TimeoutError: [WinError 10060] Une tentative de connexion a échoué car le parti connecté n’a pas répondu convenablement au-delà d’une certaine durée ou une connexion établie a échoué car l’hôte de connexion n’a pas répondu

During handling of the above exception, another exception occurred:

Traceback (most recent call last):
  File "C:/Users/valen/Desktop/Levothyscan-master/script.py", line 49, in run
    with urllib.request.urlopen(self.url) as rep:
  File "C:\Users\valen\AppData\Local\Programs\Python\Python37-32\lib\urllib\request.py", line 222, in urlopen
    return opener.open(url, data, timeout)
  File "C:\Users\valen\AppData\Local\Programs\Python\Python37-32\lib\urllib\request.py", line 525, in open
    response = self._open(req, data)
  File "C:\Users\valen\AppData\Local\Programs\Python\Python37-32\lib\urllib\request.py", line 543, in _open
    '_open', req)
  File "C:\Users\valen\AppData\Local\Programs\Python\Python37-32\lib\urllib\request.py", line 503, in _call_chain
    result = func(*args)
  File "C:\Users\valen\AppData\Local\Programs\Python\Python37-32\lib\urllib\request.py", line 1345, in http_open
    return self.do_open(http.client.HTTPConnection, req)
  File "C:\Users\valen\AppData\Local\Programs\Python\Python37-32\lib\urllib\request.py", line 1319, in do_open
    raise URLError(err)
urllib.error.URLError: <urlopen error [WinError 10060] Une tentative de connexion a échoué car le parti connecté n’a pas répondu convenablement au-delà d’une certaine durée ou une connexion établie a échoué car l’hôte de connexion n’a pas répondu>

During handling of the above exception, another exception occurred:

Traceback (most recent call last):
  File "C:\Users\valen\AppData\Local\Programs\Python\Python37-32\lib\threading.py", line 917, in _bootstrap_inner
    self.run()
  File "C:/Users/valen/Desktop/Levothyscan-master/script.py", line 51, in run
    except (http.client.IncompleteRead) as e:
NameError: name 'http' is not defined
Exception in thread Thread-327:
Traceback (most recent call last):
  File "C:\Users\valen\AppData\Local\Programs\Python\Python37-32\lib\urllib\request.py", line 1317, in do_open
    encode_chunked=req.has_header('Transfer-encoding'))
  File "C:\Users\valen\AppData\Local\Programs\Python\Python37-32\lib\http\client.py", line 1229, in request
    self._send_request(method, url, body, headers, encode_chunked)
  File "C:\Users\valen\AppData\Local\Programs\Python\Python37-32\lib\http\client.py", line 1275, in _send_request
    self.endheaders(body, encode_chunked=encode_chunked)
  File "C:\Users\valen\AppData\Local\Programs\Python\Python37-32\lib\http\client.py", line 1224, in endheaders
    self._send_output(message_body, encode_chunked=encode_chunked)
  File "C:\Users\valen\AppData\Local\Programs\Python\Python37-32\lib\http\client.py", line 1016, in _send_output
    self.send(msg)
  File "C:\Users\valen\AppData\Local\Programs\Python\Python37-32\lib\http\client.py", line 956, in send
    self.connect()
  File "C:\Users\valen\AppData\Local\Programs\Python\Python37-32\lib\http\client.py", line 928, in connect
    (self.host,self.port), self.timeout, self.source_address)
  File "C:\Users\valen\AppData\Local\Programs\Python\Python37-32\lib\socket.py", line 727, in create_connection
    raise err
  File "C:\Users\valen\AppData\Local\Programs\Python\Python37-32\lib\socket.py", line 716, in create_connection
    sock.connect(sa)
TimeoutError: [WinError 10060] Une tentative de connexion a échoué car le parti connecté n’a pas répondu convenablement au-delà d’une certaine durée ou une connexion établie a échoué car l’hôte de connexion n’a pas répondu

During handling of the above exception, another exception occurred:

Traceback (most recent call last):
  File "C:/Users/valen/Desktop/Levothyscan-master/script.py", line 49, in run
    with urllib.request.urlopen(self.url) as rep:
  File "C:\Users\valen\AppData\Local\Programs\Python\Python37-32\lib\urllib\request.py", line 222, in urlopen
    return opener.open(url, data, timeout)
  File "C:\Users\valen\AppData\Local\Programs\Python\Python37-32\lib\urllib\request.py", line 525, in open
    response = self._open(req, data)
  File "C:\Users\valen\AppData\Local\Programs\Python\Python37-32\lib\urllib\request.py", line 543, in _open
    '_open', req)
  File "C:\Users\valen\AppData\Local\Programs\Python\Python37-32\lib\urllib\request.py", line 503, in _call_chain
    result = func(*args)
  File "C:\Users\valen\AppData\Local\Programs\Python\Python37-32\lib\urllib\request.py", line 1345, in http_open
    return self.do_open(http.client.HTTPConnection, req)
  File "C:\Users\valen\AppData\Local\Programs\Python\Python37-32\lib\urllib\request.py", line 1319, in do_open
    raise URLError(err)
urllib.error.URLError: <urlopen error [WinError 10060] Une tentative de connexion a échoué car le parti connecté n’a pas répondu convenablement au-delà d’une certaine durée ou une connexion établie a échoué car l’hôte de connexion n’a pas répondu>

During handling of the above exception, another exception occurred:

Traceback (most recent call last):
  File "C:\Users\valen\AppData\Local\Programs\Python\Python37-32\lib\threading.py", line 917, in _bootstrap_inner
    self.run()
  File "C:/Users/valen/Desktop/Levothyscan-master/script.py", line 51, in run
    except (http.client.IncompleteRead) as e:
NameError: name 'http' is not defined
Exception in thread Thread-342:
Traceback (most recent call last):
  File "C:\Users\valen\AppData\Local\Programs\Python\Python37-32\lib\urllib\request.py", line 1317, in do_open
    encode_chunked=req.has_header('Transfer-encoding'))
  File "C:\Users\valen\AppData\Local\Programs\Python\Python37-32\lib\http\client.py", line 1229, in request
    self._send_request(method, url, body, headers, encode_chunked)
  File "C:\Users\valen\AppData\Local\Programs\Python\Python37-32\lib\http\client.py", line 1275, in _send_request
    self.endheaders(body, encode_chunked=encode_chunked)
  File "C:\Users\valen\AppData\Local\Programs\Python\Python37-32\lib\http\client.py", line 1224, in endheaders
    self._send_output(message_body, encode_chunked=encode_chunked)
  File "C:\Users\valen\AppData\Local\Programs\Python\Python37-32\lib\http\client.py", line 1016, in _send_output
    self.send(msg)
  File "C:\Users\valen\AppData\Local\Programs\Python\Python37-32\lib\http\client.py", line 956, in send
    self.connect()
  File "C:\Users\valen\AppData\Local\Programs\Python\Python37-32\lib\http\client.py", line 928, in connect
    (self.host,self.port), self.timeout, self.source_address)
  File "C:\Users\valen\AppData\Local\Programs\Python\Python37-32\lib\socket.py", line 727, in create_connection
    raise err
  File "C:\Users\valen\AppData\Local\Programs\Python\Python37-32\lib\socket.py", line 716, in create_connection
    sock.connect(sa)
TimeoutError: [WinError 10060] Une tentative de connexion a échoué car le parti connecté n’a pas répondu convenablement au-delà d’une certaine durée ou une connexion établie a échoué car l’hôte de connexion n’a pas répondu

During handling of the above exception, another exception occurred:

Traceback (most recent call last):
  File "C:/Users/valen/Desktop/Levothyscan-master/script.py", line 49, in run
    with urllib.request.urlopen(self.url) as rep:
  File "C:\Users\valen\AppData\Local\Programs\Python\Python37-32\lib\urllib\request.py", line 222, in urlopen
    return opener.open(url, data, timeout)
  File "C:\Users\valen\AppData\Local\Programs\Python\Python37-32\lib\urllib\request.py", line 525, in open
    response = self._open(req, data)
  File "C:\Users\valen\AppData\Local\Programs\Python\Python37-32\lib\urllib\request.py", line 543, in _open
    '_open', req)
  File "C:\Users\valen\AppData\Local\Programs\Python\Python37-32\lib\urllib\request.py", line 503, in _call_chain
    result = func(*args)
  File "C:\Users\valen\AppData\Local\Programs\Python\Python37-32\lib\urllib\request.py", line 1345, in http_open
    return self.do_open(http.client.HTTPConnection, req)
  File "C:\Users\valen\AppData\Local\Programs\Python\Python37-32\lib\urllib\request.py", line 1319, in do_open
    raise URLError(err)
urllib.error.URLError: <urlopen error [WinError 10060] Une tentative de connexion a échoué car le parti connecté n’a pas répondu convenablement au-delà d’une certaine durée ou une connexion établie a échoué car l’hôte de connexion n’a pas répondu>

During handling of the above exception, another exception occurred:

Traceback (most recent call last):
  File "C:\Users\valen\AppData\Local\Programs\Python\Python37-32\lib\threading.py", line 917, in _bootstrap_inner
    self.run()
  File "C:/Users/valen/Desktop/Levothyscan-master/script.py", line 51, in run
    except (http.client.IncompleteRead) as e:
NameError: name 'http' is not defined

Exception in thread Thread-441:
Traceback (most recent call last):
  File "C:\Users\valen\AppData\Local\Programs\Python\Python37-32\lib\urllib\request.py", line 1317, in do_open
    encode_chunked=req.has_header('Transfer-encoding'))
  File "C:\Users\valen\AppData\Local\Programs\Python\Python37-32\lib\http\client.py", line 1229, in request
    self._send_request(method, url, body, headers, encode_chunked)
  File "C:\Users\valen\AppData\Local\Programs\Python\Python37-32\lib\http\client.py", line 1275, in _send_request
    self.endheaders(body, encode_chunked=encode_chunked)
  File "C:\Users\valen\AppData\Local\Programs\Python\Python37-32\lib\http\client.py", line 1224, in endheaders
    self._send_output(message_body, encode_chunked=encode_chunked)
  File "C:\Users\valen\AppData\Local\Programs\Python\Python37-32\lib\http\client.py", line 1016, in _send_output
    self.send(msg)
  File "C:\Users\valen\AppData\Local\Programs\Python\Python37-32\lib\http\client.py", line 956, in send
    self.connect()
  File "C:\Users\valen\AppData\Local\Programs\Python\Python37-32\lib\http\client.py", line 928, in connect
    (self.host,self.port), self.timeout, self.source_address)
  File "C:\Users\valen\AppData\Local\Programs\Python\Python37-32\lib\socket.py", line 727, in create_connection
    raise err
  File "C:\Users\valen\AppData\Local\Programs\Python\Python37-32\lib\socket.py", line 716, in create_connection
    sock.connect(sa)
TimeoutError: [WinError 10060] Une tentative de connexion a échoué car le parti connecté n’a pas répondu convenablement au-delà d’une certaine durée ou une connexion établie a échoué car l’hôte de connexion n’a pas répondu

During handling of the above exception, another exception occurred:

Traceback (most recent call last):
  File "C:/Users/valen/Desktop/Levothyscan-master/script.py", line 49, in run
    with urllib.request.urlopen(self.url) as rep:
  File "C:\Users\valen\AppData\Local\Programs\Python\Python37-32\lib\urllib\request.py", line 222, in urlopen
    return opener.open(url, data, timeout)
  File "C:\Users\valen\AppData\Local\Programs\Python\Python37-32\lib\urllib\request.py", line 525, in open
    response = self._open(req, data)
  File "C:\Users\valen\AppData\Local\Programs\Python\Python37-32\lib\urllib\request.py", line 543, in _open
    '_open', req)
  File "C:\Users\valen\AppData\Local\Programs\Python\Python37-32\lib\urllib\request.py", line 503, in _call_chain
    result = func(*args)
  File "C:\Users\valen\AppData\Local\Programs\Python\Python37-32\lib\urllib\request.py", line 1345, in http_open
    return self.do_open(http.client.HTTPConnection, req)
  File "C:\Users\valen\AppData\Local\Programs\Python\Python37-32\lib\urllib\request.py", line 1319, in do_open
    raise URLError(err)
urllib.error.URLError: <urlopen error [WinError 10060] Une tentative de connexion a échoué car le parti connecté n’a pas répondu convenablement au-delà d’une certaine durée ou une connexion établie a échoué car l’hôte de connexion n’a pas répondu>

During handling of the above exception, another exception occurred:

Traceback (most recent call last):
  File "C:\Users\valen\AppData\Local\Programs\Python\Python37-32\lib\threading.py", line 917, in _bootstrap_inner
    self.run()
  File "C:/Users/valen/Desktop/Levothyscan-master/script.py", line 51, in run
    except (http.client.IncompleteRead) as e:
NameError: name 'http' is not defined
Exception in thread Thread-417:
Traceback (most recent call last):
  File "C:\Users\valen\AppData\Local\Programs\Python\Python37-32\lib\urllib\request.py", line 1317, in do_open
    encode_chunked=req.has_header('Transfer-encoding'))
  File "C:\Users\valen\AppData\Local\Programs\Python\Python37-32\lib\http\client.py", line 1229, in request
    self._send_request(method, url, body, headers, encode_chunked)
  File "C:\Users\valen\AppData\Local\Programs\Python\Python37-32\lib\http\client.py", line 1275, in _send_request
    self.endheaders(body, encode_chunked=encode_chunked)
  File "C:\Users\valen\AppData\Local\Programs\Python\Python37-32\lib\http\client.py", line 1224, in endheaders
    self._send_output(message_body, encode_chunked=encode_chunked)
  File "C:\Users\valen\AppData\Local\Programs\Python\Python37-32\lib\http\client.py", line 1016, in _send_output
    self.send(msg)
  File "C:\Users\valen\AppData\Local\Programs\Python\Python37-32\lib\http\client.py", line 956, in send
    self.connect()
  File "C:\Users\valen\AppData\Local\Programs\Python\Python37-32\lib\http\client.py", line 928, in connect
    (self.host,self.port), self.timeout, self.source_address)
  File "C:\Users\valen\AppData\Local\Programs\Python\Python37-32\lib\socket.py", line 727, in create_connection
    raise err
  File "C:\Users\valen\AppData\Local\Programs\Python\Python37-32\lib\socket.py", line 716, in create_connection
    sock.connect(sa)
TimeoutError: [WinError 10060] Une tentative de connexion a échoué car le parti connecté n’a pas répondu convenablement au-delà d’une certaine durée ou une connexion établie a échoué car l’hôte de connexion n’a pas répondu

During handling of the above exception, another exception occurred:

Traceback (most recent call last):
  File "C:/Users/valen/Desktop/Levothyscan-master/script.py", line 49, in run
    with urllib.request.urlopen(self.url) as rep:
  File "C:\Users\valen\AppData\Local\Programs\Python\Python37-32\lib\urllib\request.py", line 222, in urlopen
    return opener.open(url, data, timeout)
  File "C:\Users\valen\AppData\Local\Programs\Python\Python37-32\lib\urllib\request.py", line 525, in open
    response = self._open(req, data)
  File "C:\Users\valen\AppData\Local\Programs\Python\Python37-32\lib\urllib\request.py", line 543, in _open
    '_open', req)
  File "C:\Users\valen\AppData\Local\Programs\Python\Python37-32\lib\urllib\request.py", line 503, in _call_chain
    result = func(*args)
  File "C:\Users\valen\AppData\Local\Programs\Python\Python37-32\lib\urllib\request.py", line 1345, in http_open
    return self.do_open(http.client.HTTPConnection, req)
  File "C:\Users\valen\AppData\Local\Programs\Python\Python37-32\lib\urllib\request.py", line 1319, in do_open
    raise URLError(err)
urllib.error.URLError: <urlopen error [WinError 10060] Une tentative de connexion a échoué car le parti connecté n’a pas répondu convenablement au-delà d’une certaine durée ou une connexion établie a échoué car l’hôte de connexion n’a pas répondu>

During handling of the above exception, another exception occurred:

Traceback (most recent call last):
  File "C:\Users\valen\AppData\Local\Programs\Python\Python37-32\lib\threading.py", line 917, in _bootstrap_inner
    self.run()
  File "C:/Users/valen/Desktop/Levothyscan-master/script.py", line 51, in run
    except (http.client.IncompleteRead) as e:
NameError: name 'http' is not defined
Exception in thread Thread-375:
Traceback (most recent call last):
  File "C:\Users\valen\AppData\Local\Programs\Python\Python37-32\lib\urllib\request.py", line 1317, in do_open
    encode_chunked=req.has_header('Transfer-encoding'))
  File "C:\Users\valen\AppData\Local\Programs\Python\Python37-32\lib\http\client.py", line 1229, in request
    self._send_request(method, url, body, headers, encode_chunked)
  File "C:\Users\valen\AppData\Local\Programs\Python\Python37-32\lib\http\client.py", line 1275, in _send_request
    self.endheaders(body, encode_chunked=encode_chunked)
  File "C:\Users\valen\AppData\Local\Programs\Python\Python37-32\lib\http\client.py", line 1224, in endheaders
    self._send_output(message_body, encode_chunked=encode_chunked)
  File "C:\Users\valen\AppData\Local\Programs\Python\Python37-32\lib\http\client.py", line 1016, in _send_output
    self.send(msg)
  File "C:\Users\valen\AppData\Local\Programs\Python\Python37-32\lib\http\client.py", line 956, in send
    self.connect()
  File "C:\Users\valen\AppData\Local\Programs\Python\Python37-32\lib\http\client.py", line 928, in connect
    (self.host,self.port), self.timeout, self.source_address)
  File "C:\Users\valen\AppData\Local\Programs\Python\Python37-32\lib\socket.py", line 727, in create_connection
    raise err
  File "C:\Users\valen\AppData\Local\Programs\Python\Python37-32\lib\socket.py", line 716, in create_connection
    sock.connect(sa)
TimeoutError: [WinError 10060] Une tentative de connexion a échoué car le parti connecté n’a pas répondu convenablement au-delà d’une certaine durée ou une connexion établie a échoué car l’hôte de connexion n’a pas répondu

During handling of the above exception, another exception occurred:

Traceback (most recent call last):
  File "C:/Users/valen/Desktop/Levothyscan-master/script.py", line 49, in run
    with urllib.request.urlopen(self.url) as rep:
  File "C:\Users\valen\AppData\Local\Programs\Python\Python37-32\lib\urllib\request.py", line 222, in urlopen
    return opener.open(url, data, timeout)
  File "C:\Users\valen\AppData\Local\Programs\Python\Python37-32\lib\urllib\request.py", line 525, in open
    response = self._open(req, data)
  File "C:\Users\valen\AppData\Local\Programs\Python\Python37-32\lib\urllib\request.py", line 543, in _open
    '_open', req)
  File "C:\Users\valen\AppData\Local\Programs\Python\Python37-32\lib\urllib\request.py", line 503, in _call_chain
    result = func(*args)
  File "C:\Users\valen\AppData\Local\Programs\Python\Python37-32\lib\urllib\request.py", line 1345, in http_open
    return self.do_open(http.client.HTTPConnection, req)
  File "C:\Users\valen\AppData\Local\Programs\Python\Python37-32\lib\urllib\request.py", line 1319, in do_open
    raise URLError(err)
urllib.error.URLError: <urlopen error [WinError 10060] Une tentative de connexion a échoué car le parti connecté n’a pas répondu convenablement au-delà d’une certaine durée ou une connexion établie a échoué car l’hôte de connexion n’a pas répondu>

During handling of the above exception, another exception occurred:

Traceback (most recent call last):
  File "C:\Users\valen\AppData\Local\Programs\Python\Python37-32\lib\threading.py", line 917, in _bootstrap_inner
    self.run()
  File "C:/Users/valen/Desktop/Levothyscan-master/script.py", line 51, in run
    except (http.client.IncompleteRead) as e:
NameError: name 'http' is not defined
Exception in thread Thread-398:
Traceback (most recent call last):
  File "C:\Users\valen\AppData\Local\Programs\Python\Python37-32\lib\urllib\request.py", line 1317, in do_open
    encode_chunked=req.has_header('Transfer-encoding'))
  File "C:\Users\valen\AppData\Local\Programs\Python\Python37-32\lib\http\client.py", line 1229, in request
    self._send_request(method, url, body, headers, encode_chunked)
  File "C:\Users\valen\AppData\Local\Programs\Python\Python37-32\lib\http\client.py", line 1275, in _send_request
    self.endheaders(body, encode_chunked=encode_chunked)
  File "C:\Users\valen\AppData\Local\Programs\Python\Python37-32\lib\http\client.py", line 1224, in endheaders
    self._send_output(message_body, encode_chunked=encode_chunked)
  File "C:\Users\valen\AppData\Local\Programs\Python\Python37-32\lib\http\client.py", line 1016, in _send_output
    self.send(msg)
  File "C:\Users\valen\AppData\Local\Programs\Python\Python37-32\lib\http\client.py", line 956, in send
    self.connect()
  File "C:\Users\valen\AppData\Local\Programs\Python\Python37-32\lib\http\client.py", line 928, in connect
    (self.host,self.port), self.timeout, self.source_address)
  File "C:\Users\valen\AppData\Local\Programs\Python\Python37-32\lib\socket.py", line 727, in create_connection
    raise err
  File "C:\Users\valen\AppData\Local\Programs\Python\Python37-32\lib\socket.py", line 716, in create_connection
    sock.connect(sa)
TimeoutError: [WinError 10060] Une tentative de connexion a échoué car le parti connecté n’a pas répondu convenablement au-delà d’une certaine durée ou une connexion établie a échoué car l’hôte de connexion n’a pas répondu

During handling of the above exception, another exception occurred:

Traceback (most recent call last):
  File "C:/Users/valen/Desktop/Levothyscan-master/script.py", line 49, in run
    with urllib.request.urlopen(self.url) as rep:
  File "C:\Users\valen\AppData\Local\Programs\Python\Python37-32\lib\urllib\request.py", line 222, in urlopen
    return opener.open(url, data, timeout)
  File "C:\Users\valen\AppData\Local\Programs\Python\Python37-32\lib\urllib\request.py", line 525, in open
    response = self._open(req, data)
  File "C:\Users\valen\AppData\Local\Programs\Python\Python37-32\lib\urllib\request.py", line 543, in _open
    '_open', req)
  File "C:\Users\valen\AppData\Local\Programs\Python\Python37-32\lib\urllib\request.py", line 503, in _call_chain
    result = func(*args)
  File "C:\Users\valen\AppData\Local\Programs\Python\Python37-32\lib\urllib\request.py", line 1345, in http_open
    return self.do_open(http.client.HTTPConnection, req)
  File "C:\Users\valen\AppData\Local\Programs\Python\Python37-32\lib\urllib\request.py", line 1319, in do_open
    raise URLError(err)
urllib.error.URLError: <urlopen error [WinError 10060] Une tentative de connexion a échoué car le parti connecté n’a pas répondu convenablement au-delà d’une certaine durée ou une connexion établie a échoué car l’hôte de connexion n’a pas répondu>

During handling of the above exception, another exception occurred:

Traceback (most recent call last):
  File "C:\Users\valen\AppData\Local\Programs\Python\Python37-32\lib\threading.py", line 917, in _bootstrap_inner
    self.run()
  File "C:/Users/valen/Desktop/Levothyscan-master/script.py", line 51, in run
    except (http.client.IncompleteRead) as e:
NameError: name 'http' is not defined





Exception in thread Thread-442:
Traceback (most recent call last):
  File "C:\Users\valen\AppData\Local\Programs\Python\Python37-32\lib\urllib\request.py", line 1317, in do_open
    encode_chunked=req.has_header('Transfer-encoding'))
  File "C:\Users\valen\AppData\Local\Programs\Python\Python37-32\lib\http\client.py", line 1229, in request
    self._send_request(method, url, body, headers, encode_chunked)
  File "C:\Users\valen\AppData\Local\Programs\Python\Python37-32\lib\http\client.py", line 1275, in _send_request
    self.endheaders(body, encode_chunked=encode_chunked)
  File "C:\Users\valen\AppData\Local\Programs\Python\Python37-32\lib\http\client.py", line 1224, in endheaders
    self._send_output(message_body, encode_chunked=encode_chunked)
  File "C:\Users\valen\AppData\Local\Programs\Python\Python37-32\lib\http\client.py", line 1016, in _send_output
    self.send(msg)
  File "C:\Users\valen\AppData\Local\Programs\Python\Python37-32\lib\http\client.py", line 956, in send
    self.connect()
  File "C:\Users\valen\AppData\Local\Programs\Python\Python37-32\lib\http\client.py", line 928, in connect
    (self.host,self.port), self.timeout, self.source_address)
  File "C:\Users\valen\AppData\Local\Programs\Python\Python37-32\lib\socket.py", line 727, in create_connection
    raise err
  File "C:\Users\valen\AppData\Local\Programs\Python\Python37-32\lib\socket.py", line 716, in create_connection
    sock.connect(sa)
TimeoutError: [WinError 10060] Une tentative de connexion a échoué car le parti connecté n’a pas répondu convenablement au-delà d’une certaine durée ou une connexion établie a échoué car l’hôte de connexion n’a pas répondu

During handling of the above exception, another exception occurred:

Traceback (most recent call last):
  File "C:/Users/valen/Desktop/Levothyscan-master/script.py", line 49, in run
    with urllib.request.urlopen(self.url) as rep:
  File "C:\Users\valen\AppData\Local\Programs\Python\Python37-32\lib\urllib\request.py", line 222, in urlopen
    return opener.open(url, data, timeout)
  File "C:\Users\valen\AppData\Local\Programs\Python\Python37-32\lib\urllib\request.py", line 525, in open
    response = self._open(req, data)
  File "C:\Users\valen\AppData\Local\Programs\Python\Python37-32\lib\urllib\request.py", line 543, in _open
    '_open', req)
  File "C:\Users\valen\AppData\Local\Programs\Python\Python37-32\lib\urllib\request.py", line 503, in _call_chain
    result = func(*args)
  File "C:\Users\valen\AppData\Local\Programs\Python\Python37-32\lib\urllib\request.py", line 1345, in http_open
    return self.do_open(http.client.HTTPConnection, req)
  File "C:\Users\valen\AppData\Local\Programs\Python\Python37-32\lib\urllib\request.py", line 1319, in do_open
    raise URLError(err)
urllib.error.URLError: <urlopen error [WinError 10060] Une tentative de connexion a échoué car le parti connecté n’a pas répondu convenablement au-delà d’une certaine durée ou une connexion établie a échoué car l’hôte de connexion n’a pas répondu>

During handling of the above exception, another exception occurred:

Traceback (most recent call last):
  File "C:\Users\valen\AppData\Local\Programs\Python\Python37-32\lib\threading.py", line 917, in _bootstrap_inner
    self.run()
  File "C:/Users/valen/Desktop/Levothyscan-master/script.py", line 51, in run
    except (http.client.IncompleteRead) as e:
NameError: name 'http' is not defined

Exception in thread Thread-449:
Traceback (most recent call last):
  File "C:\Users\valen\AppData\Local\Programs\Python\Python37-32\lib\urllib\request.py", line 1317, in do_open
    encode_chunked=req.has_header('Transfer-encoding'))
  File "C:\Users\valen\AppData\Local\Programs\Python\Python37-32\lib\http\client.py", line 1229, in request
    self._send_request(method, url, body, headers, encode_chunked)
  File "C:\Users\valen\AppData\Local\Programs\Python\Python37-32\lib\http\client.py", line 1275, in _send_request
    self.endheaders(body, encode_chunked=encode_chunked)
  File "C:\Users\valen\AppData\Local\Programs\Python\Python37-32\lib\http\client.py", line 1224, in endheaders
    self._send_output(message_body, encode_chunked=encode_chunked)
  File "C:\Users\valen\AppData\Local\Programs\Python\Python37-32\lib\http\client.py", line 1016, in _send_output
    self.send(msg)
  File "C:\Users\valen\AppData\Local\Programs\Python\Python37-32\lib\http\client.py", line 956, in send
    self.connect()
  File "C:\Users\valen\AppData\Local\Programs\Python\Python37-32\lib\http\client.py", line 928, in connect
    (self.host,self.port), self.timeout, self.source_address)
  File "C:\Users\valen\AppData\Local\Programs\Python\Python37-32\lib\socket.py", line 727, in create_connection
    raise err
  File "C:\Users\valen\AppData\Local\Programs\Python\Python37-32\lib\socket.py", line 716, in create_connection
    sock.connect(sa)
TimeoutError: [WinError 10060] Une tentative de connexion a échoué car le parti connecté n’a pas répondu convenablement au-delà d’une certaine durée ou une connexion établie a échoué car l’hôte de connexion n’a pas répondu

During handling of the above exception, another exception occurred:

Traceback (most recent call last):
  File "C:/Users/valen/Desktop/Levothyscan-master/script.py", line 49, in run
    with urllib.request.urlopen(self.url) as rep:
  File "C:\Users\valen\AppData\Local\Programs\Python\Python37-32\lib\urllib\request.py", line 222, in urlopen
    return opener.open(url, data, timeout)
  File "C:\Users\valen\AppData\Local\Programs\Python\Python37-32\lib\urllib\request.py", line 525, in open
    response = self._open(req, data)
  File "C:\Users\valen\AppData\Local\Programs\Python\Python37-32\lib\urllib\request.py", line 543, in _open
    '_open', req)
  File "C:\Users\valen\AppData\Local\Programs\Python\Python37-32\lib\urllib\request.py", line 503, in _call_chain
    result = func(*args)
  File "C:\Users\valen\AppData\Local\Programs\Python\Python37-32\lib\urllib\request.py", line 1345, in http_open
    return self.do_open(http.client.HTTPConnection, req)
  File "C:\Users\valen\AppData\Local\Programs\Python\Python37-32\lib\urllib\request.py", line 1319, in do_open
    raise URLError(err)
urllib.error.URLError: <urlopen error [WinError 10060] Une tentative de connexion a échoué car le parti connecté n’a pas répondu convenablement au-delà d’une certaine durée ou une connexion établie a échoué car l’hôte de connexion n’a pas répondu>

During handling of the above exception, another exception occurred:

Traceback (most recent call last):
  File "C:\Users\valen\AppData\Local\Programs\Python\Python37-32\lib\threading.py", line 917, in _bootstrap_inner
    self.run()
  File "C:/Users/valen/Desktop/Levothyscan-master/script.py", line 51, in run
    except (http.client.IncompleteRead) as e:
NameError: name 'http' is not defined

Exception in thread Thread-455:
Traceback (most recent call last):
  File "C:\Users\valen\AppData\Local\Programs\Python\Python37-32\lib\urllib\request.py", line 1317, in do_open
    encode_chunked=req.has_header('Transfer-encoding'))
  File "C:\Users\valen\AppData\Local\Programs\Python\Python37-32\lib\http\client.py", line 1229, in request
    self._send_request(method, url, body, headers, encode_chunked)
  File "C:\Users\valen\AppData\Local\Programs\Python\Python37-32\lib\http\client.py", line 1275, in _send_request
    self.endheaders(body, encode_chunked=encode_chunked)
  File "C:\Users\valen\AppData\Local\Programs\Python\Python37-32\lib\http\client.py", line 1224, in endheaders
    self._send_output(message_body, encode_chunked=encode_chunked)
  File "C:\Users\valen\AppData\Local\Programs\Python\Python37-32\lib\http\client.py", line 1016, in _send_output
    self.send(msg)
  File "C:\Users\valen\AppData\Local\Programs\Python\Python37-32\lib\http\client.py", line 956, in send
    self.connect()
  File "C:\Users\valen\AppData\Local\Programs\Python\Python37-32\lib\http\client.py", line 928, in connect
    (self.host,self.port), self.timeout, self.source_address)
  File "C:\Users\valen\AppData\Local\Programs\Python\Python37-32\lib\socket.py", line 727, in create_connection
    raise err
  File "C:\Users\valen\AppData\Local\Programs\Python\Python37-32\lib\socket.py", line 716, in create_connection
    sock.connect(sa)
TimeoutError: [WinError 10060] Une tentative de connexion a échoué car le parti connecté n’a pas répondu convenablement au-delà d’une certaine durée ou une connexion établie a échoué car l’hôte de connexion n’a pas répondu

During handling of the above exception, another exception occurred:

Traceback (most recent call last):
  File "C:/Users/valen/Desktop/Levothyscan-master/script.py", line 49, in run
    with urllib.request.urlopen(self.url) as rep:
  File "C:\Users\valen\AppData\Local\Programs\Python\Python37-32\lib\urllib\request.py", line 222, in urlopen
    return opener.open(url, data, timeout)
  File "C:\Users\valen\AppData\Local\Programs\Python\Python37-32\lib\urllib\request.py", line 525, in open
    response = self._open(req, data)
  File "C:\Users\valen\AppData\Local\Programs\Python\Python37-32\lib\urllib\request.py", line 543, in _open
    '_open', req)
  File "C:\Users\valen\AppData\Local\Programs\Python\Python37-32\lib\urllib\request.py", line 503, in _call_chain
    result = func(*args)
  File "C:\Users\valen\AppData\Local\Programs\Python\Python37-32\lib\urllib\request.py", line 1345, in http_open
    return self.do_open(http.client.HTTPConnection, req)
  File "C:\Users\valen\AppData\Local\Programs\Python\Python37-32\lib\urllib\request.py", line 1319, in do_open
    raise URLError(err)
urllib.error.URLError: <urlopen error [WinError 10060] Une tentative de connexion a échoué car le parti connecté n’a pas répondu convenablement au-delà d’une certaine durée ou une connexion établie a échoué car l’hôte de connexion n’a pas répondu>

During handling of the above exception, another exception occurred:

Traceback (most recent call last):
  File "C:\Users\valen\AppData\Local\Programs\Python\Python37-32\lib\threading.py", line 917, in _bootstrap_inner
    self.run()
  File "C:/Users/valen/Desktop/Levothyscan-master/script.py", line 51, in run
    except (http.client.IncompleteRead) as e:
NameError: name 'http' is not defined

Exception in thread Thread-324:
Traceback (most recent call last):
  File "C:\Users\valen\AppData\Local\Programs\Python\Python37-32\lib\urllib\request.py", line 1317, in do_open
    encode_chunked=req.has_header('Transfer-encoding'))
  File "C:\Users\valen\AppData\Local\Programs\Python\Python37-32\lib\http\client.py", line 1229, in request
    self._send_request(method, url, body, headers, encode_chunked)
  File "C:\Users\valen\AppData\Local\Programs\Python\Python37-32\lib\http\client.py", line 1275, in _send_request
    self.endheaders(body, encode_chunked=encode_chunked)
  File "C:\Users\valen\AppData\Local\Programs\Python\Python37-32\lib\http\client.py", line 1224, in endheaders
    self._send_output(message_body, encode_chunked=encode_chunked)
  File "C:\Users\valen\AppData\Local\Programs\Python\Python37-32\lib\http\client.py", line 1016, in _send_output
    self.send(msg)
  File "C:\Users\valen\AppData\Local\Programs\Python\Python37-32\lib\http\client.py", line 956, in send
    self.connect()
  File "C:\Users\valen\AppData\Local\Programs\Python\Python37-32\lib\http\client.py", line 928, in connect
    (self.host,self.port), self.timeout, self.source_address)
  File "C:\Users\valen\AppData\Local\Programs\Python\Python37-32\lib\socket.py", line 727, in create_connection
    raise err
  File "C:\Users\valen\AppData\Local\Programs\Python\Python37-32\lib\socket.py", line 716, in create_connection
    sock.connect(sa)
TimeoutError: [WinError 10060] Une tentative de connexion a échoué car le parti connecté n’a pas répondu convenablement au-delà d’une certaine durée ou une connexion établie a échoué car l’hôte de connexion n’a pas répondu

During handling of the above exception, another exception occurred:

Traceback (most recent call last):
  File "C:/Users/valen/Desktop/Levothyscan-master/script.py", line 49, in run
    with urllib.request.urlopen(self.url) as rep:
  File "C:\Users\valen\AppData\Local\Programs\Python\Python37-32\lib\urllib\request.py", line 222, in urlopen
    return opener.open(url, data, timeout)
  File "C:\Users\valen\AppData\Local\Programs\Python\Python37-32\lib\urllib\request.py", line 525, in open
    response = self._open(req, data)
  File "C:\Users\valen\AppData\Local\Programs\Python\Python37-32\lib\urllib\request.py", line 543, in _open
    '_open', req)
  File "C:\Users\valen\AppData\Local\Programs\Python\Python37-32\lib\urllib\request.py", line 503, in _call_chain
    result = func(*args)
  File "C:\Users\valen\AppData\Local\Programs\Python\Python37-32\lib\urllib\request.py", line 1345, in http_open
    return self.do_open(http.client.HTTPConnection, req)
  File "C:\Users\valen\AppData\Local\Programs\Python\Python37-32\lib\urllib\request.py", line 1319, in do_open
    raise URLError(err)
urllib.error.URLError: <urlopen error [WinError 10060] Une tentative de connexion a échoué car le parti connecté n’a pas répondu convenablement au-delà d’une certaine durée ou une connexion établie a échoué car l’hôte de connexion n’a pas répondu>

During handling of the above exception, another exception occurred:

Traceback (most recent call last):
  File "C:\Users\valen\AppData\Local\Programs\Python\Python37-32\lib\threading.py", line 917, in _bootstrap_inner
    self.run()
  File "C:/Users/valen/Desktop/Levothyscan-master/script.py", line 51, in run
    except (http.client.IncompleteRead) as e:
NameError: name 'http' is not defined
Exception in thread Thread-472:
Traceback (most recent call last):
  File "C:\Users\valen\AppData\Local\Programs\Python\Python37-32\lib\urllib\request.py", line 1317, in do_open
    encode_chunked=req.has_header('Transfer-encoding'))
  File "C:\Users\valen\AppData\Local\Programs\Python\Python37-32\lib\http\client.py", line 1229, in request
    self._send_request(method, url, body, headers, encode_chunked)
  File "C:\Users\valen\AppData\Local\Programs\Python\Python37-32\lib\http\client.py", line 1275, in _send_request
    self.endheaders(body, encode_chunked=encode_chunked)
  File "C:\Users\valen\AppData\Local\Programs\Python\Python37-32\lib\http\client.py", line 1224, in endheaders
    self._send_output(message_body, encode_chunked=encode_chunked)
  File "C:\Users\valen\AppData\Local\Programs\Python\Python37-32\lib\http\client.py", line 1016, in _send_output
    self.send(msg)
  File "C:\Users\valen\AppData\Local\Programs\Python\Python37-32\lib\http\client.py", line 956, in send
    self.connect()
  File "C:\Users\valen\AppData\Local\Programs\Python\Python37-32\lib\http\client.py", line 928, in connect
    (self.host,self.port), self.timeout, self.source_address)
  File "C:\Users\valen\AppData\Local\Programs\Python\Python37-32\lib\socket.py", line 727, in create_connection
    raise err
  File "C:\Users\valen\AppData\Local\Programs\Python\Python37-32\lib\socket.py", line 716, in create_connection
    sock.connect(sa)
TimeoutError: [WinError 10060] Une tentative de connexion a échoué car le parti connecté n’a pas répondu convenablement au-delà d’une certaine durée ou une connexion établie a échoué car l’hôte de connexion n’a pas répondu

During handling of the above exception, another exception occurred:

Traceback (most recent call last):
  File "C:/Users/valen/Desktop/Levothyscan-master/script.py", line 49, in run
    with urllib.request.urlopen(self.url) as rep:
  File "C:\Users\valen\AppData\Local\Programs\Python\Python37-32\lib\urllib\request.py", line 222, in urlopen
    return opener.open(url, data, timeout)
  File "C:\Users\valen\AppData\Local\Programs\Python\Python37-32\lib\urllib\request.py", line 525, in open
    response = self._open(req, data)
  File "C:\Users\valen\AppData\Local\Programs\Python\Python37-32\lib\urllib\request.py", line 543, in _open
    '_open', req)
  File "C:\Users\valen\AppData\Local\Programs\Python\Python37-32\lib\urllib\request.py", line 503, in _call_chain
    result = func(*args)
  File "C:\Users\valen\AppData\Local\Programs\Python\Python37-32\lib\urllib\request.py", line 1345, in http_open
    return self.do_open(http.client.HTTPConnection, req)
  File "C:\Users\valen\AppData\Local\Programs\Python\Python37-32\lib\urllib\request.py", line 1319, in do_open
    raise URLError(err)
urllib.error.URLError: <urlopen error [WinError 10060] Une tentative de connexion a échoué car le parti connecté n’a pas répondu convenablement au-delà d’une certaine durée ou une connexion établie a échoué car l’hôte de connexion n’a pas répondu>

During handling of the above exception, another exception occurred:

Traceback (most recent call last):
  File "C:\Users\valen\AppData\Local\Programs\Python\Python37-32\lib\threading.py", line 917, in _bootstrap_inner
    self.run()
  File "C:/Users/valen/Desktop/Levothyscan-master/script.py", line 51, in run
    except (http.client.IncompleteRead) as e:
NameError: name 'http' is not defined



Exception in thread Thread-497:
Traceback (most recent call last):
  File "C:\Users\valen\AppData\Local\Programs\Python\Python37-32\lib\urllib\request.py", line 1317, in do_open
    encode_chunked=req.has_header('Transfer-encoding'))
  File "C:\Users\valen\AppData\Local\Programs\Python\Python37-32\lib\http\client.py", line 1229, in request
    self._send_request(method, url, body, headers, encode_chunked)
  File "C:\Users\valen\AppData\Local\Programs\Python\Python37-32\lib\http\client.py", line 1275, in _send_request
    self.endheaders(body, encode_chunked=encode_chunked)
  File "C:\Users\valen\AppData\Local\Programs\Python\Python37-32\lib\http\client.py", line 1224, in endheaders
    self._send_output(message_body, encode_chunked=encode_chunked)
  File "C:\Users\valen\AppData\Local\Programs\Python\Python37-32\lib\http\client.py", line 1016, in _send_output
    self.send(msg)
  File "C:\Users\valen\AppData\Local\Programs\Python\Python37-32\lib\http\client.py", line 956, in send
    self.connect()
  File "C:\Users\valen\AppData\Local\Programs\Python\Python37-32\lib\http\client.py", line 928, in connect
    (self.host,self.port), self.timeout, self.source_address)
  File "C:\Users\valen\AppData\Local\Programs\Python\Python37-32\lib\socket.py", line 727, in create_connection
    raise err
  File "C:\Users\valen\AppData\Local\Programs\Python\Python37-32\lib\socket.py", line 716, in create_connection
    sock.connect(sa)
TimeoutError: [WinError 10060] Une tentative de connexion a échoué car le parti connecté n’a pas répondu convenablement au-delà d’une certaine durée ou une connexion établie a échoué car l’hôte de connexion n’a pas répondu

During handling of the above exception, another exception occurred:

Traceback (most recent call last):
  File "C:/Users/valen/Desktop/Levothyscan-master/script.py", line 49, in run
    with urllib.request.urlopen(self.url) as rep:
  File "C:\Users\valen\AppData\Local\Programs\Python\Python37-32\lib\urllib\request.py", line 222, in urlopen
    return opener.open(url, data, timeout)
  File "C:\Users\valen\AppData\Local\Programs\Python\Python37-32\lib\urllib\request.py", line 525, in open
    response = self._open(req, data)
  File "C:\Users\valen\AppData\Local\Programs\Python\Python37-32\lib\urllib\request.py", line 543, in _open
    '_open', req)
  File "C:\Users\valen\AppData\Local\Programs\Python\Python37-32\lib\urllib\request.py", line 503, in _call_chain
    result = func(*args)
  File "C:\Users\valen\AppData\Local\Programs\Python\Python37-32\lib\urllib\request.py", line 1345, in http_open
    return self.do_open(http.client.HTTPConnection, req)
  File "C:\Users\valen\AppData\Local\Programs\Python\Python37-32\lib\urllib\request.py", line 1319, in do_open
    raise URLError(err)
urllib.error.URLError: <urlopen error [WinError 10060] Une tentative de connexion a échoué car le parti connecté n’a pas répondu convenablement au-delà d’une certaine durée ou une connexion établie a échoué car l’hôte de connexion n’a pas répondu>

During handling of the above exception, another exception occurred:

Traceback (most recent call last):
  File "C:\Users\valen\AppData\Local\Programs\Python\Python37-32\lib\threading.py", line 917, in _bootstrap_inner
    self.run()
  File "C:/Users/valen/Desktop/Levothyscan-master/script.py", line 51, in run
    except (http.client.IncompleteRead) as e:
NameError: name 'http' is not defined

Exception in thread Thread-503:
Traceback (most recent call last):
  File "C:\Users\valen\AppData\Local\Programs\Python\Python37-32\lib\urllib\request.py", line 1317, in do_open
    encode_chunked=req.has_header('Transfer-encoding'))
  File "C:\Users\valen\AppData\Local\Programs\Python\Python37-32\lib\http\client.py", line 1229, in request
    self._send_request(method, url, body, headers, encode_chunked)
  File "C:\Users\valen\AppData\Local\Programs\Python\Python37-32\lib\http\client.py", line 1275, in _send_request
    self.endheaders(body, encode_chunked=encode_chunked)
  File "C:\Users\valen\AppData\Local\Programs\Python\Python37-32\lib\http\client.py", line 1224, in endheaders
    self._send_output(message_body, encode_chunked=encode_chunked)
  File "C:\Users\valen\AppData\Local\Programs\Python\Python37-32\lib\http\client.py", line 1016, in _send_output
    self.send(msg)
  File "C:\Users\valen\AppData\Local\Programs\Python\Python37-32\lib\http\client.py", line 956, in send
    self.connect()
  File "C:\Users\valen\AppData\Local\Programs\Python\Python37-32\lib\http\client.py", line 928, in connect
    (self.host,self.port), self.timeout, self.source_address)
  File "C:\Users\valen\AppData\Local\Programs\Python\Python37-32\lib\socket.py", line 727, in create_connection
    raise err
  File "C:\Users\valen\AppData\Local\Programs\Python\Python37-32\lib\socket.py", line 716, in create_connection
    sock.connect(sa)
TimeoutError: [WinError 10060] Une tentative de connexion a échoué car le parti connecté n’a pas répondu convenablement au-delà d’une certaine durée ou une connexion établie a échoué car l’hôte de connexion n’a pas répondu

During handling of the above exception, another exception occurred:

Traceback (most recent call last):
  File "C:/Users/valen/Desktop/Levothyscan-master/script.py", line 49, in run
    with urllib.request.urlopen(self.url) as rep:
  File "C:\Users\valen\AppData\Local\Programs\Python\Python37-32\lib\urllib\request.py", line 222, in urlopen
    return opener.open(url, data, timeout)
  File "C:\Users\valen\AppData\Local\Programs\Python\Python37-32\lib\urllib\request.py", line 525, in open
    response = self._open(req, data)
  File "C:\Users\valen\AppData\Local\Programs\Python\Python37-32\lib\urllib\request.py", line 543, in _open
    '_open', req)
  File "C:\Users\valen\AppData\Local\Programs\Python\Python37-32\lib\urllib\request.py", line 503, in _call_chain
    result = func(*args)
  File "C:\Users\valen\AppData\Local\Programs\Python\Python37-32\lib\urllib\request.py", line 1345, in http_open
    return self.do_open(http.client.HTTPConnection, req)
  File "C:\Users\valen\AppData\Local\Programs\Python\Python37-32\lib\urllib\request.py", line 1319, in do_open
    raise URLError(err)
urllib.error.URLError: <urlopen error [WinError 10060] Une tentative de connexion a échoué car le parti connecté n’a pas répondu convenablement au-delà d’une certaine durée ou une connexion établie a échoué car l’hôte de connexion n’a pas répondu>

During handling of the above exception, another exception occurred:

Traceback (most recent call last):
  File "C:\Users\valen\AppData\Local\Programs\Python\Python37-32\lib\threading.py", line 917, in _bootstrap_inner
    self.run()
  File "C:/Users/valen/Desktop/Levothyscan-master/script.py", line 51, in run
    except (http.client.IncompleteRead) as e:
NameError: name 'http' is not defined

Exception in thread Thread-521:
Traceback (most recent call last):
  File "C:\Users\valen\AppData\Local\Programs\Python\Python37-32\lib\urllib\request.py", line 1317, in do_open
    encode_chunked=req.has_header('Transfer-encoding'))
  File "C:\Users\valen\AppData\Local\Programs\Python\Python37-32\lib\http\client.py", line 1229, in request
    self._send_request(method, url, body, headers, encode_chunked)
  File "C:\Users\valen\AppData\Local\Programs\Python\Python37-32\lib\http\client.py", line 1275, in _send_request
    self.endheaders(body, encode_chunked=encode_chunked)
  File "C:\Users\valen\AppData\Local\Programs\Python\Python37-32\lib\http\client.py", line 1224, in endheaders
    self._send_output(message_body, encode_chunked=encode_chunked)
  File "C:\Users\valen\AppData\Local\Programs\Python\Python37-32\lib\http\client.py", line 1016, in _send_output
    self.send(msg)
  File "C:\Users\valen\AppData\Local\Programs\Python\Python37-32\lib\http\client.py", line 956, in send
    self.connect()
  File "C:\Users\valen\AppData\Local\Programs\Python\Python37-32\lib\http\client.py", line 928, in connect
    (self.host,self.port), self.timeout, self.source_address)
  File "C:\Users\valen\AppData\Local\Programs\Python\Python37-32\lib\socket.py", line 727, in create_connection
    raise err
  File "C:\Users\valen\AppData\Local\Programs\Python\Python37-32\lib\socket.py", line 716, in create_connection
    sock.connect(sa)
TimeoutError: [WinError 10060] Une tentative de connexion a échoué car le parti connecté n’a pas répondu convenablement au-delà d’une certaine durée ou une connexion établie a échoué car l’hôte de connexion n’a pas répondu

During handling of the above exception, another exception occurred:

Traceback (most recent call last):
  File "C:/Users/valen/Desktop/Levothyscan-master/script.py", line 49, in run
    with urllib.request.urlopen(self.url) as rep:
  File "C:\Users\valen\AppData\Local\Programs\Python\Python37-32\lib\urllib\request.py", line 222, in urlopen
    return opener.open(url, data, timeout)
  File "C:\Users\valen\AppData\Local\Programs\Python\Python37-32\lib\urllib\request.py", line 525, in open
    response = self._open(req, data)
  File "C:\Users\valen\AppData\Local\Programs\Python\Python37-32\lib\urllib\request.py", line 543, in _open
    '_open', req)
  File "C:\Users\valen\AppData\Local\Programs\Python\Python37-32\lib\urllib\request.py", line 503, in _call_chain
    result = func(*args)
  File "C:\Users\valen\AppData\Local\Programs\Python\Python37-32\lib\urllib\request.py", line 1345, in http_open
    return self.do_open(http.client.HTTPConnection, req)
  File "C:\Users\valen\AppData\Local\Programs\Python\Python37-32\lib\urllib\request.py", line 1319, in do_open
    raise URLError(err)
urllib.error.URLError: <urlopen error [WinError 10060] Une tentative de connexion a échoué car le parti connecté n’a pas répondu convenablement au-delà d’une certaine durée ou une connexion établie a échoué car l’hôte de connexion n’a pas répondu>

During handling of the above exception, another exception occurred:

Traceback (most recent call last):
  File "C:\Users\valen\AppData\Local\Programs\Python\Python37-32\lib\threading.py", line 917, in _bootstrap_inner
    self.run()
  File "C:/Users/valen/Desktop/Levothyscan-master/script.py", line 51, in run
    except (http.client.IncompleteRead) as e:
NameError: name 'http' is not defined

Exception in thread Thread-532:
Traceback (most recent call last):
  File "C:\Users\valen\AppData\Local\Programs\Python\Python37-32\lib\urllib\request.py", line 1317, in do_open
    encode_chunked=req.has_header('Transfer-encoding'))
  File "C:\Users\valen\AppData\Local\Programs\Python\Python37-32\lib\http\client.py", line 1229, in request
    self._send_request(method, url, body, headers, encode_chunked)
  File "C:\Users\valen\AppData\Local\Programs\Python\Python37-32\lib\http\client.py", line 1275, in _send_request
    self.endheaders(body, encode_chunked=encode_chunked)
  File "C:\Users\valen\AppData\Local\Programs\Python\Python37-32\lib\http\client.py", line 1224, in endheaders
    self._send_output(message_body, encode_chunked=encode_chunked)
  File "C:\Users\valen\AppData\Local\Programs\Python\Python37-32\lib\http\client.py", line 1016, in _send_output
    self.send(msg)
  File "C:\Users\valen\AppData\Local\Programs\Python\Python37-32\lib\http\client.py", line 956, in send
    self.connect()
  File "C:\Users\valen\AppData\Local\Programs\Python\Python37-32\lib\http\client.py", line 928, in connect
    (self.host,self.port), self.timeout, self.source_address)
  File "C:\Users\valen\AppData\Local\Programs\Python\Python37-32\lib\socket.py", line 727, in create_connection
    raise err
  File "C:\Users\valen\AppData\Local\Programs\Python\Python37-32\lib\socket.py", line 716, in create_connection
    sock.connect(sa)
TimeoutError: [WinError 10060] Une tentative de connexion a échoué car le parti connecté n’a pas répondu convenablement au-delà d’une certaine durée ou une connexion établie a échoué car l’hôte de connexion n’a pas répondu

During handling of the above exception, another exception occurred:

Traceback (most recent call last):
  File "C:/Users/valen/Desktop/Levothyscan-master/script.py", line 49, in run
    with urllib.request.urlopen(self.url) as rep:
  File "C:\Users\valen\AppData\Local\Programs\Python\Python37-32\lib\urllib\request.py", line 222, in urlopen
    return opener.open(url, data, timeout)
  File "C:\Users\valen\AppData\Local\Programs\Python\Python37-32\lib\urllib\request.py", line 525, in open
    response = self._open(req, data)
  File "C:\Users\valen\AppData\Local\Programs\Python\Python37-32\lib\urllib\request.py", line 543, in _open
    '_open', req)
  File "C:\Users\valen\AppData\Local\Programs\Python\Python37-32\lib\urllib\request.py", line 503, in _call_chain
    result = func(*args)
  File "C:\Users\valen\AppData\Local\Programs\Python\Python37-32\lib\urllib\request.py", line 1345, in http_open
    return self.do_open(http.client.HTTPConnection, req)
  File "C:\Users\valen\AppData\Local\Programs\Python\Python37-32\lib\urllib\request.py", line 1319, in do_open
    raise URLError(err)
urllib.error.URLError: <urlopen error [WinError 10060] Une tentative de connexion a échoué car le parti connecté n’a pas répondu convenablement au-delà d’une certaine durée ou une connexion établie a échoué car l’hôte de connexion n’a pas répondu>

During handling of the above exception, another exception occurred:

Traceback (most recent call last):
  File "C:\Users\valen\AppData\Local\Programs\Python\Python37-32\lib\threading.py", line 917, in _bootstrap_inner
    self.run()
  File "C:/Users/valen/Desktop/Levothyscan-master/script.py", line 51, in run
    except (http.client.IncompleteRead) as e:
NameError: name 'http' is not defined

Exception in thread Thread-537:
Traceback (most recent call last):
  File "C:\Users\valen\AppData\Local\Programs\Python\Python37-32\lib\urllib\request.py", line 1317, in do_open
    encode_chunked=req.has_header('Transfer-encoding'))
  File "C:\Users\valen\AppData\Local\Programs\Python\Python37-32\lib\http\client.py", line 1229, in request
    self._send_request(method, url, body, headers, encode_chunked)
  File "C:\Users\valen\AppData\Local\Programs\Python\Python37-32\lib\http\client.py", line 1275, in _send_request
    self.endheaders(body, encode_chunked=encode_chunked)
  File "C:\Users\valen\AppData\Local\Programs\Python\Python37-32\lib\http\client.py", line 1224, in endheaders
    self._send_output(message_body, encode_chunked=encode_chunked)
  File "C:\Users\valen\AppData\Local\Programs\Python\Python37-32\lib\http\client.py", line 1016, in _send_output
    self.send(msg)
  File "C:\Users\valen\AppData\Local\Programs\Python\Python37-32\lib\http\client.py", line 956, in send
    self.connect()
  File "C:\Users\valen\AppData\Local\Programs\Python\Python37-32\lib\http\client.py", line 928, in connect
    (self.host,self.port), self.timeout, self.source_address)
  File "C:\Users\valen\AppData\Local\Programs\Python\Python37-32\lib\socket.py", line 727, in create_connection
    raise err
  File "C:\Users\valen\AppData\Local\Programs\Python\Python37-32\lib\socket.py", line 716, in create_connection
    sock.connect(sa)
TimeoutError: [WinError 10060] Une tentative de connexion a échoué car le parti connecté n’a pas répondu convenablement au-delà d’une certaine durée ou une connexion établie a échoué car l’hôte de connexion n’a pas répondu

During handling of the above exception, another exception occurred:

Traceback (most recent call last):
  File "C:/Users/valen/Desktop/Levothyscan-master/script.py", line 49, in run
    with urllib.request.urlopen(self.url) as rep:
  File "C:\Users\valen\AppData\Local\Programs\Python\Python37-32\lib\urllib\request.py", line 222, in urlopen
    return opener.open(url, data, timeout)
  File "C:\Users\valen\AppData\Local\Programs\Python\Python37-32\lib\urllib\request.py", line 525, in open
    response = self._open(req, data)
  File "C:\Users\valen\AppData\Local\Programs\Python\Python37-32\lib\urllib\request.py", line 543, in _open
    '_open', req)
  File "C:\Users\valen\AppData\Local\Programs\Python\Python37-32\lib\urllib\request.py", line 503, in _call_chain
    result = func(*args)
  File "C:\Users\valen\AppData\Local\Programs\Python\Python37-32\lib\urllib\request.py", line 1345, in http_open
    return self.do_open(http.client.HTTPConnection, req)
  File "C:\Users\valen\AppData\Local\Programs\Python\Python37-32\lib\urllib\request.py", line 1319, in do_open
    raise URLError(err)
urllib.error.URLError: <urlopen error [WinError 10060] Une tentative de connexion a échoué car le parti connecté n’a pas répondu convenablement au-delà d’une certaine durée ou une connexion établie a échoué car l’hôte de connexion n’a pas répondu>

During handling of the above exception, another exception occurred:

Traceback (most recent call last):
  File "C:\Users\valen\AppData\Local\Programs\Python\Python37-32\lib\threading.py", line 917, in _bootstrap_inner
    self.run()
  File "C:/Users/valen/Desktop/Levothyscan-master/script.py", line 51, in run
    except (http.client.IncompleteRead) as e:
NameError: name 'http' is not defined

Exception in thread Thread-552:
Traceback (most recent call last):
  File "C:\Users\valen\AppData\Local\Programs\Python\Python37-32\lib\urllib\request.py", line 1317, in do_open
    encode_chunked=req.has_header('Transfer-encoding'))
  File "C:\Users\valen\AppData\Local\Programs\Python\Python37-32\lib\http\client.py", line 1229, in request
    self._send_request(method, url, body, headers, encode_chunked)
  File "C:\Users\valen\AppData\Local\Programs\Python\Python37-32\lib\http\client.py", line 1275, in _send_request
    self.endheaders(body, encode_chunked=encode_chunked)
  File "C:\Users\valen\AppData\Local\Programs\Python\Python37-32\lib\http\client.py", line 1224, in endheaders
    self._send_output(message_body, encode_chunked=encode_chunked)
  File "C:\Users\valen\AppData\Local\Programs\Python\Python37-32\lib\http\client.py", line 1016, in _send_output
    self.send(msg)
  File "C:\Users\valen\AppData\Local\Programs\Python\Python37-32\lib\http\client.py", line 956, in send
    self.connect()
  File "C:\Users\valen\AppData\Local\Programs\Python\Python37-32\lib\http\client.py", line 928, in connect
    (self.host,self.port), self.timeout, self.source_address)
  File "C:\Users\valen\AppData\Local\Programs\Python\Python37-32\lib\socket.py", line 727, in create_connection
    raise err
  File "C:\Users\valen\AppData\Local\Programs\Python\Python37-32\lib\socket.py", line 716, in create_connection
    sock.connect(sa)
TimeoutError: [WinError 10060] Une tentative de connexion a échoué car le parti connecté n’a pas répondu convenablement au-delà d’une certaine durée ou une connexion établie a échoué car l’hôte de connexion n’a pas répondu

During handling of the above exception, another exception occurred:

Traceback (most recent call last):
  File "C:/Users/valen/Desktop/Levothyscan-master/script.py", line 49, in run
    with urllib.request.urlopen(self.url) as rep:
  File "C:\Users\valen\AppData\Local\Programs\Python\Python37-32\lib\urllib\request.py", line 222, in urlopen
    return opener.open(url, data, timeout)
  File "C:\Users\valen\AppData\Local\Programs\Python\Python37-32\lib\urllib\request.py", line 525, in open
    response = self._open(req, data)
  File "C:\Users\valen\AppData\Local\Programs\Python\Python37-32\lib\urllib\request.py", line 543, in _open
    '_open', req)
  File "C:\Users\valen\AppData\Local\Programs\Python\Python37-32\lib\urllib\request.py", line 503, in _call_chain
    result = func(*args)
  File "C:\Users\valen\AppData\Local\Programs\Python\Python37-32\lib\urllib\request.py", line 1345, in http_open
    return self.do_open(http.client.HTTPConnection, req)
  File "C:\Users\valen\AppData\Local\Programs\Python\Python37-32\lib\urllib\request.py", line 1319, in do_open
    raise URLError(err)
urllib.error.URLError: <urlopen error [WinError 10060] Une tentative de connexion a échoué car le parti connecté n’a pas répondu convenablement au-delà d’une certaine durée ou une connexion établie a échoué car l’hôte de connexion n’a pas répondu>

During handling of the above exception, another exception occurred:

Traceback (most recent call last):
  File "C:\Users\valen\AppData\Local\Programs\Python\Python37-32\lib\threading.py", line 917, in _bootstrap_inner
    self.run()
  File "C:/Users/valen/Desktop/Levothyscan-master/script.py", line 51, in run
    except (http.client.IncompleteRead) as e:
NameError: name 'http' is not defined

Exception in thread Thread-550:
Traceback (most recent call last):
  File "C:\Users\valen\AppData\Local\Programs\Python\Python37-32\lib\urllib\request.py", line 1317, in do_open
    encode_chunked=req.has_header('Transfer-encoding'))
  File "C:\Users\valen\AppData\Local\Programs\Python\Python37-32\lib\http\client.py", line 1229, in request
    self._send_request(method, url, body, headers, encode_chunked)
  File "C:\Users\valen\AppData\Local\Programs\Python\Python37-32\lib\http\client.py", line 1275, in _send_request
    self.endheaders(body, encode_chunked=encode_chunked)
  File "C:\Users\valen\AppData\Local\Programs\Python\Python37-32\lib\http\client.py", line 1224, in endheaders
    self._send_output(message_body, encode_chunked=encode_chunked)
  File "C:\Users\valen\AppData\Local\Programs\Python\Python37-32\lib\http\client.py", line 1016, in _send_output
    self.send(msg)
  File "C:\Users\valen\AppData\Local\Programs\Python\Python37-32\lib\http\client.py", line 956, in send
    self.connect()
  File "C:\Users\valen\AppData\Local\Programs\Python\Python37-32\lib\http\client.py", line 928, in connect
    (self.host,self.port), self.timeout, self.source_address)
  File "C:\Users\valen\AppData\Local\Programs\Python\Python37-32\lib\socket.py", line 727, in create_connection
    raise err
  File "C:\Users\valen\AppData\Local\Programs\Python\Python37-32\lib\socket.py", line 716, in create_connection
    sock.connect(sa)
TimeoutError: [WinError 10060] Une tentative de connexion a échoué car le parti connecté n’a pas répondu convenablement au-delà d’une certaine durée ou une connexion établie a échoué car l’hôte de connexion n’a pas répondu

During handling of the above exception, another exception occurred:

Traceback (most recent call last):
  File "C:/Users/valen/Desktop/Levothyscan-master/script.py", line 49, in run
    with urllib.request.urlopen(self.url) as rep:
  File "C:\Users\valen\AppData\Local\Programs\Python\Python37-32\lib\urllib\request.py", line 222, in urlopen
    return opener.open(url, data, timeout)
  File "C:\Users\valen\AppData\Local\Programs\Python\Python37-32\lib\urllib\request.py", line 525, in open
    response = self._open(req, data)
  File "C:\Users\valen\AppData\Local\Programs\Python\Python37-32\lib\urllib\request.py", line 543, in _open
    '_open', req)
  File "C:\Users\valen\AppData\Local\Programs\Python\Python37-32\lib\urllib\request.py", line 503, in _call_chain
    result = func(*args)
  File "C:\Users\valen\AppData\Local\Programs\Python\Python37-32\lib\urllib\request.py", line 1345, in http_open
    return self.do_open(http.client.HTTPConnection, req)
  File "C:\Users\valen\AppData\Local\Programs\Python\Python37-32\lib\urllib\request.py", line 1319, in do_open
    raise URLError(err)
urllib.error.URLError: <urlopen error [WinError 10060] Une tentative de connexion a échoué car le parti connecté n’a pas répondu convenablement au-delà d’une certaine durée ou une connexion établie a échoué car l’hôte de connexion n’a pas répondu>

During handling of the above exception, another exception occurred:

Traceback (most recent call last):
  File "C:\Users\valen\AppData\Local\Programs\Python\Python37-32\lib\threading.py", line 917, in _bootstrap_inner
    self.run()
  File "C:/Users/valen/Desktop/Levothyscan-master/script.py", line 51, in run
    except (http.client.IncompleteRead) as e:
NameError: name 'http' is not defined

Exception in thread Thread-557:
Traceback (most recent call last):
  File "C:\Users\valen\AppData\Local\Programs\Python\Python37-32\lib\urllib\request.py", line 1317, in do_open
    encode_chunked=req.has_header('Transfer-encoding'))
  File "C:\Users\valen\AppData\Local\Programs\Python\Python37-32\lib\http\client.py", line 1229, in request
    self._send_request(method, url, body, headers, encode_chunked)
  File "C:\Users\valen\AppData\Local\Programs\Python\Python37-32\lib\http\client.py", line 1275, in _send_request
    self.endheaders(body, encode_chunked=encode_chunked)
  File "C:\Users\valen\AppData\Local\Programs\Python\Python37-32\lib\http\client.py", line 1224, in endheaders
    self._send_output(message_body, encode_chunked=encode_chunked)
  File "C:\Users\valen\AppData\Local\Programs\Python\Python37-32\lib\http\client.py", line 1016, in _send_output
    self.send(msg)
  File "C:\Users\valen\AppData\Local\Programs\Python\Python37-32\lib\http\client.py", line 956, in send
    self.connect()
  File "C:\Users\valen\AppData\Local\Programs\Python\Python37-32\lib\http\client.py", line 928, in connect
    (self.host,self.port), self.timeout, self.source_address)
  File "C:\Users\valen\AppData\Local\Programs\Python\Python37-32\lib\socket.py", line 727, in create_connection
    raise err
  File "C:\Users\valen\AppData\Local\Programs\Python\Python37-32\lib\socket.py", line 716, in create_connection
    sock.connect(sa)
TimeoutError: [WinError 10060] Une tentative de connexion a échoué car le parti connecté n’a pas répondu convenablement au-delà d’une certaine durée ou une connexion établie a échoué car l’hôte de connexion n’a pas répondu

During handling of the above exception, another exception occurred:

Traceback (most recent call last):
  File "C:/Users/valen/Desktop/Levothyscan-master/script.py", line 49, in run
    with urllib.request.urlopen(self.url) as rep:
  File "C:\Users\valen\AppData\Local\Programs\Python\Python37-32\lib\urllib\request.py", line 222, in urlopen
    return opener.open(url, data, timeout)
  File "C:\Users\valen\AppData\Local\Programs\Python\Python37-32\lib\urllib\request.py", line 525, in open
    response = self._open(req, data)
  File "C:\Users\valen\AppData\Local\Programs\Python\Python37-32\lib\urllib\request.py", line 543, in _open
    '_open', req)
  File "C:\Users\valen\AppData\Local\Programs\Python\Python37-32\lib\urllib\request.py", line 503, in _call_chain
    result = func(*args)
  File "C:\Users\valen\AppData\Local\Programs\Python\Python37-32\lib\urllib\request.py", line 1345, in http_open
    return self.do_open(http.client.HTTPConnection, req)
  File "C:\Users\valen\AppData\Local\Programs\Python\Python37-32\lib\urllib\request.py", line 1319, in do_open
    raise URLError(err)
urllib.error.URLError: <urlopen error [WinError 10060] Une tentative de connexion a échoué car le parti connecté n’a pas répondu convenablement au-delà d’une certaine durée ou une connexion établie a échoué car l’hôte de connexion n’a pas répondu>

During handling of the above exception, another exception occurred:

Traceback (most recent call last):
  File "C:\Users\valen\AppData\Local\Programs\Python\Python37-32\lib\threading.py", line 917, in _bootstrap_inner
    self.run()
  File "C:/Users/valen/Desktop/Levothyscan-master/script.py", line 51, in run
    except (http.client.IncompleteRead) as e:
NameError: name 'http' is not defined

Exception in thread Thread-556:
Traceback (most recent call last):
  File "C:\Users\valen\AppData\Local\Programs\Python\Python37-32\lib\urllib\request.py", line 1317, in do_open
    encode_chunked=req.has_header('Transfer-encoding'))
  File "C:\Users\valen\AppData\Local\Programs\Python\Python37-32\lib\http\client.py", line 1229, in request
    self._send_request(method, url, body, headers, encode_chunked)
  File "C:\Users\valen\AppData\Local\Programs\Python\Python37-32\lib\http\client.py", line 1275, in _send_request
    self.endheaders(body, encode_chunked=encode_chunked)
  File "C:\Users\valen\AppData\Local\Programs\Python\Python37-32\lib\http\client.py", line 1224, in endheaders
    self._send_output(message_body, encode_chunked=encode_chunked)
  File "C:\Users\valen\AppData\Local\Programs\Python\Python37-32\lib\http\client.py", line 1016, in _send_output
    self.send(msg)
  File "C:\Users\valen\AppData\Local\Programs\Python\Python37-32\lib\http\client.py", line 956, in send
    self.connect()
  File "C:\Users\valen\AppData\Local\Programs\Python\Python37-32\lib\http\client.py", line 928, in connect
    (self.host,self.port), self.timeout, self.source_address)
  File "C:\Users\valen\AppData\Local\Programs\Python\Python37-32\lib\socket.py", line 727, in create_connection
    raise err
  File "C:\Users\valen\AppData\Local\Programs\Python\Python37-32\lib\socket.py", line 716, in create_connection
    sock.connect(sa)
TimeoutError: [WinError 10060] Une tentative de connexion a échoué car le parti connecté n’a pas répondu convenablement au-delà d’une certaine durée ou une connexion établie a échoué car l’hôte de connexion n’a pas répondu

During handling of the above exception, another exception occurred:

Traceback (most recent call last):
  File "C:/Users/valen/Desktop/Levothyscan-master/script.py", line 49, in run
    with urllib.request.urlopen(self.url) as rep:
  File "C:\Users\valen\AppData\Local\Programs\Python\Python37-32\lib\urllib\request.py", line 222, in urlopen
    return opener.open(url, data, timeout)
  File "C:\Users\valen\AppData\Local\Programs\Python\Python37-32\lib\urllib\request.py", line 525, in open
    response = self._open(req, data)
  File "C:\Users\valen\AppData\Local\Programs\Python\Python37-32\lib\urllib\request.py", line 543, in _open
    '_open', req)
  File "C:\Users\valen\AppData\Local\Programs\Python\Python37-32\lib\urllib\request.py", line 503, in _call_chain
    result = func(*args)
  File "C:\Users\valen\AppData\Local\Programs\Python\Python37-32\lib\urllib\request.py", line 1345, in http_open
    return self.do_open(http.client.HTTPConnection, req)
  File "C:\Users\valen\AppData\Local\Programs\Python\Python37-32\lib\urllib\request.py", line 1319, in do_open
    raise URLError(err)
urllib.error.URLError: <urlopen error [WinError 10060] Une tentative de connexion a échoué car le parti connecté n’a pas répondu convenablement au-delà d’une certaine durée ou une connexion établie a échoué car l’hôte de connexion n’a pas répondu>

During handling of the above exception, another exception occurred:

Traceback (most recent call last):
  File "C:\Users\valen\AppData\Local\Programs\Python\Python37-32\lib\threading.py", line 917, in _bootstrap_inner
    self.run()
  File "C:/Users/valen/Desktop/Levothyscan-master/script.py", line 51, in run
    except (http.client.IncompleteRead) as e:
NameError: name 'http' is not defined

Exception in thread Thread-563:
Traceback (most recent call last):
  File "C:\Users\valen\AppData\Local\Programs\Python\Python37-32\lib\urllib\request.py", line 1317, in do_open
    encode_chunked=req.has_header('Transfer-encoding'))
  File "C:\Users\valen\AppData\Local\Programs\Python\Python37-32\lib\http\client.py", line 1229, in request
    self._send_request(method, url, body, headers, encode_chunked)
  File "C:\Users\valen\AppData\Local\Programs\Python\Python37-32\lib\http\client.py", line 1275, in _send_request
    self.endheaders(body, encode_chunked=encode_chunked)
  File "C:\Users\valen\AppData\Local\Programs\Python\Python37-32\lib\http\client.py", line 1224, in endheaders
    self._send_output(message_body, encode_chunked=encode_chunked)
  File "C:\Users\valen\AppData\Local\Programs\Python\Python37-32\lib\http\client.py", line 1016, in _send_output
    self.send(msg)
  File "C:\Users\valen\AppData\Local\Programs\Python\Python37-32\lib\http\client.py", line 956, in send
    self.connect()
  File "C:\Users\valen\AppData\Local\Programs\Python\Python37-32\lib\http\client.py", line 928, in connect
    (self.host,self.port), self.timeout, self.source_address)
  File "C:\Users\valen\AppData\Local\Programs\Python\Python37-32\lib\socket.py", line 727, in create_connection
    raise err
  File "C:\Users\valen\AppData\Local\Programs\Python\Python37-32\lib\socket.py", line 716, in create_connection
    sock.connect(sa)
TimeoutError: [WinError 10060] Une tentative de connexion a échoué car le parti connecté n’a pas répondu convenablement au-delà d’une certaine durée ou une connexion établie a échoué car l’hôte de connexion n’a pas répondu

During handling of the above exception, another exception occurred:

Traceback (most recent call last):
  File "C:/Users/valen/Desktop/Levothyscan-master/script.py", line 49, in run
    with urllib.request.urlopen(self.url) as rep:
  File "C:\Users\valen\AppData\Local\Programs\Python\Python37-32\lib\urllib\request.py", line 222, in urlopen
    return opener.open(url, data, timeout)
  File "C:\Users\valen\AppData\Local\Programs\Python\Python37-32\lib\urllib\request.py", line 525, in open
    response = self._open(req, data)
  File "C:\Users\valen\AppData\Local\Programs\Python\Python37-32\lib\urllib\request.py", line 543, in _open
    '_open', req)
  File "C:\Users\valen\AppData\Local\Programs\Python\Python37-32\lib\urllib\request.py", line 503, in _call_chain
    result = func(*args)
  File "C:\Users\valen\AppData\Local\Programs\Python\Python37-32\lib\urllib\request.py", line 1345, in http_open
    return self.do_open(http.client.HTTPConnection, req)
  File "C:\Users\valen\AppData\Local\Programs\Python\Python37-32\lib\urllib\request.py", line 1319, in do_open
    raise URLError(err)
urllib.error.URLError: <urlopen error [WinError 10060] Une tentative de connexion a échoué car le parti connecté n’a pas répondu convenablement au-delà d’une certaine durée ou une connexion établie a échoué car l’hôte de connexion n’a pas répondu>

During handling of the above exception, another exception occurred:

Traceback (most recent call last):
  File "C:\Users\valen\AppData\Local\Programs\Python\Python37-32\lib\threading.py", line 917, in _bootstrap_inner
    self.run()
  File "C:/Users/valen/Desktop/Levothyscan-master/script.py", line 51, in run
    except (http.client.IncompleteRead) as e:
NameError: name 'http' is not defined

